<?xml version="1.0" ?>
<!-- =================================================================================== -->
<!-- |    This document was autogenerated by xacro from /home/cobracommander/modular_mbrl/mbrl/urdf/llnnll.xacro | -->
<!-- |    EDITING THIS FILE BY HAND IS NOT RECOMMENDED                                 | -->
<!-- =================================================================================== -->
<robot name="llnnll" xmlns:xacro="http://www.ros.org/wiki/xacro">
  <!-- This is a single xacro file you can include to get
  all of the HEBI components -->
  <!-- <xacro:include filename="end_effector.xacro"/> -->
  <!-- This automatically loads the gazebo plugin for xacro models
       which include hebi.xacro 
  <gazebo>
    <plugin name="hebi_gazebo_plugin" filename="libhebi_gazebo_plugin.so"/>
  </gazebo>-->
  <link name="chassis">
    <visual>
      <geometry>
        <mesh filename="base_plate.stl" scale="0.001 0.001 0.001"/>
      </geometry>
      <origin rpy="1.57079632679 0 1.57079632679" xyz="0 0 0"/>
      <material name="silver">
        <color rgba="0.6 0.6 0.6 1"/>
      </material>
    </visual>
    <collision>
      <geometry>
        <mesh filename="base_plate.stl" scale="0.001 0.001 0.001"/>
      </geometry>
      <origin rpy="1.57079632679 0 1.57079632679" xyz="0 0 0"/>
    </collision>
    <inertial>
      <!--mass value="2.7"/no battery-->
      <mass value="3.4"/>
      <!-- with  1 battery -->
      <inertia ixx="0.02" ixy="0.0" ixz="0.0" iyy="0.02" iyz="0.0" izz="0.05"/>
      <origin rpy="0 0 0" xyz="-0.02 0 0"/>
    </inertial>
    <visual>
      <geometry>
        <box size="0.15 0.02 0.02"/>
      </geometry>
      <origin rpy="0 0 0" xyz="0.075 0 0.0195"/>
      <material name="silver">
        <color rgba="0.6 0.6 0.6 1"/>
      </material>
    </visual>
  </link>
  <geometry>
    <box size="0.15 0.02 0.02"/>
  </geometry>
  <origin rpy="0 0 0" xyz="0.01 0 0.0345"/>
  <!-- connect leg to chassis -->
  <joint name="base_leg_1" type="fixed">
    <parent link="chassis"/>
    <child link="leg_1/J1_base/INPUT_INTERFACE"/>
    <origin rpy="0 0 -1.0471975512" xyz="0.1524 0.0880 0.0095"/>
  </joint>
  <link name="leg_1/J1_base/INPUT_INTERFACE">
    <visual>
      <origin rpy="0 0 0" xyz="0 0 0.02"/>
      <geometry>
        <cylinder length="0.04" radius="0.035"/>
      </geometry>
      <material name="red">
        <color rgba=".82 0.06 0.06 1"/>
      </material>
    </visual>
    <collision>
      <origin rpy="0 0 0" xyz="0 0 0.02"/>
      <geometry>
        <cylinder length="0.04" radius="0.035"/>
      </geometry>
    </collision>
    <inertial>
      <origin rpy="0 0 0" xyz="-0.0145 -0.0031 0.0242"/>
      <mass value="0.48"/>
      <inertia ixx="0.000246" ixy="0.0000444" ixz="0.0000266" iyy="0.000380" iyz="0.00000422" izz="0.000463"/>
    </inertial>
  </link>
  <joint name="leg_1/J1_base/X8_9" type="revolute">
    <parent link="leg_1/J1_base/INPUT_INTERFACE"/>
    <child link="leg_1/shoulder_bracket/INPUT_INTERFACE"/>
    <origin rpy="0 0 0" xyz="0 0 0.045"/>
    <axis xyz="0 0 1"/>
    <limit effort="20" lower="0.523598775598" upper="2.61799387799" velocity="3.14"/>
    <dynamics damping="0.5" friction="0.5"/>
  </joint>
  <link name="leg_1/shoulder_bracket/INPUT_INTERFACE">
    <!-- REMOVED VISUAL AND COLLISION FOR SPEED
      <visual>
        <xacro:if value="${bracket_type.endswith('RightOutside')}">
          <origin xyz="0 0 0.005" rpy="${pi/2} 0 ${pi/2}"/>
        </xacro:if>
        <xacro:if value="${bracket_type.endswith('RightInside')}">
          <origin xyz="0 0 0.005" rpy="${pi/2} 0 ${-pi/2}"/>
        </xacro:if>
        <xacro:if value="${bracket_type.endswith('LeftOutside')}">
          <origin xyz="0 0 0.005" rpy="${pi/2} 0 ${-pi/2}"/>
        </xacro:if>
        <xacro:if value="${bracket_type.endswith('LeftInside')}">
          <origin xyz="0 0 0.005" rpy="${pi/2} 0 ${pi/2}"/>
        </xacro:if>
        <geometry>
          <mesh filename="PM-2149-01.stl" scale="0.001 0.001 0.001"/>
        </geometry>
        <xacro:black_material/>
      </visual>
      <visual>
        <xacro:if value="${bracket_type.endswith('RightOutside')}">
          <origin xyz="0 -.03 .04" rpy="${pi/2} 0 0"/>
        </xacro:if>
        <xacro:if value="${bracket_type.endswith('RightInside')}">
          <origin xyz="0 .03 .04" rpy="${pi/2} 0 0"/>
        </xacro:if>
        <xacro:if value="${bracket_type.endswith('LeftOutside')}">
          <origin xyz="0 -.03 .04" rpy="${pi/2} 0 0"/>
        </xacro:if>
        <xacro:if value="${bracket_type.endswith('LeftInside')}">
          <origin xyz="0 -.03 .04" rpy="${pi/2} 0 ${pi}"/>
        </xacro:if>
        <geometry>
          <xacro:if value="${bracket_type.startswith('X5HeavyRight') or bracket_type.startswith('R5HeavyRight')}">
            <mesh filename="PM-2150-01R.stl" scale="0.001 0.001 0.001"/>
          </xacro:if>
          <xacro:if value="${bracket_type.startswith('X5HeavyLeft') or bracket_type.startswith('R5HeavyLeft')}">
            <mesh filename="PM-2150-01L.stl" scale="0.001 0.001 0.001"/>
          </xacro:if>
        </geometry>
        <xacro:black_material/>
      </visual>

      <collision>
        <xacro:if value="${bracket_type.endswith('RightOutside')}">
          <origin xyz="0 0 0.005" rpy="${pi/2} 0 ${pi/2}"/>
        </xacro:if>
        <xacro:if value="${bracket_type.endswith('RightInside')}">
          <origin xyz="0 0 0.005" rpy="${pi/2} 0 ${-pi/2}"/>
        </xacro:if>
        <xacro:if value="${bracket_type.endswith('LeftOutside')}">
          <origin xyz="0 0 0.005" rpy="${pi/2} 0 ${-pi/2}"/>
        </xacro:if>
        <xacro:if value="${bracket_type.endswith('LeftInside')}">
          <origin xyz="0 0 0.005" rpy="${pi/2} 0 ${pi/2}"/>
        </xacro:if>
        <geometry>
          <mesh filename="PM-2149-01.stl" scale="0.001 0.001 0.001"/>
        </geometry>
      </collision>
      <collision>
        <xacro:if value="${bracket_type.endswith('RightOutside')}">
          <origin xyz="0 -.03 .04" rpy="${pi/2} 0 0"/>
        </xacro:if>
        <xacro:if value="${bracket_type.endswith('RightInside')}">
          <origin xyz="0 .03 .04" rpy="${pi/2} 0 0"/>
        </xacro:if>
        <xacro:if value="${bracket_type.endswith('LeftOutside')}">
          <origin xyz="0 .03 .04" rpy="${pi/2} 0 ${pi}"/>
        </xacro:if>
        <xacro:if value="${bracket_type.endswith('LeftInside')}">
          <origin xyz="0 -.03 .04" rpy="${pi/2} 0 ${pi}"/>
        </xacro:if>
        <geometry>
          <xacro:if value="${bracket_type.startswith('X5HeavyRight') or bracket_type.startswith('R5HeavyRight')}">
            <mesh filename="PM-2150-01R.stl" scale="0.001 0.001 0.001"/>
          </xacro:if>
          <xacro:if value="${bracket_type.startswith('X5HeavyLeft') or bracket_type.startswith('R5HeavyLeft')}">
            <mesh filename="PM-2150-01L.stl" scale="0.001 0.001 0.001"/>
          </xacro:if>
        </geometry>
      </collision>
      -->
    <!-- NOTE: inertia is just modelled as small sphere, and could be improved. -->
    <inertial>
      <origin rpy="0 0 0" xyz="0 0.01125 .0275"/>
      <mass value="0.215"/>
      <inertia ixx="0.0003096" ixy="0.0" ixz="0.0" iyy="0.0003096" iyz="0.0" izz="0.0003096"/>
    </inertial>
  </link>
  <joint name="leg_1/shoulder_bracket/OUTPUT_INTERFACE" type="fixed">
    <parent link="leg_1/shoulder_bracket/INPUT_INTERFACE"/>
    <child link="leg_1/J2_shoulder/INPUT_INTERFACE"/>
    <origin rpy="1.57079632679 0 0" xyz="0 .0225 .055"/>
  </joint>
  <link name="leg_1/J2_shoulder/INPUT_INTERFACE">
    <visual>
      <origin rpy="0 0 0" xyz="0 0 0.02"/>
      <geometry>
        <cylinder length="0.04" radius="0.035"/>
      </geometry>
      <material name="red">
        <color rgba=".82 0.06 0.06 1"/>
      </material>
    </visual>
    <collision>
      <origin rpy="0 0 0" xyz="0 0 0.02"/>
      <geometry>
        <cylinder length="0.04" radius="0.035"/>
      </geometry>
    </collision>
    <inertial>
      <origin rpy="0 0 0" xyz="-0.0145 -0.0031 0.0242"/>
      <mass value="0.5"/>
      <inertia ixx="0.000246" ixy="0.0000444" ixz="0.0000266" iyy="0.000380" iyz="0.00000422" izz="0.000463"/>
    </inertial>
  </link>
  <joint name="leg_1/J2_shoulder/X8_16" type="revolute">
    <parent link="leg_1/J2_shoulder/INPUT_INTERFACE"/>
    <child link="leg_1/shoulder_elbow/INPUT_INTERFACE"/>
    <origin rpy="0 0 0" xyz="0 0 0.045"/>
    <axis xyz="0 0 1"/>
    <limit effort="38" lower="-0.785398163397" upper="0.785398163397" velocity="1.571"/>
    <dynamics damping="0.5" friction="0.5"/>
  </joint>
  <link name="leg_1/shoulder_elbow/INPUT_INTERFACE">
    <!--visual>
        <origin xyz="0 0 0" rpy="0 0 0" />
        <geometry>
          <mesh filename="package://hebi_description/meshes/A-2038-02.stl"/>
        </geometry>
        <xacro:black_material/>
      </visual-->
    <visual>
      <origin rpy="0 1.57075 0" xyz="0.1375 0 0.02"/>
      <geometry>
        <cylinder length="0.2496" radius=".016"/>
      </geometry>
      <material name="silver">
        <color rgba="0.6 0.6 0.6 1"/>
      </material>
    </visual>
    <!--visual>
        <origin xyz="${extension} ${sin(-twist) * edge_to_center} ${edge_to_center * (1 + cos(-twist))}" rpy="${-twist} 0 0"/>
        <geometry>
          <mesh filename="package://hebi_description/meshes/A-2039-02.stl"/>
        </geometry>
        <xacro:black_material/>
      </visual-->
    <!--collision>
        <origin xyz="0 0 0" rpy="0 0 0" />
        <geometry>
          <mesh filename="package://hebi_description/meshes/A-2038-02.stl"/>
        </geometry>
      </collision-->
    <collision>
      <origin rpy="0 1.57075 0" xyz="0.1375 0 0.02"/>
      <geometry>
        <cylinder length="0.2496" radius=".016"/>
      </geometry>
    </collision>
    <!--collision>
        <origin xyz="${extension} ${sin(-twist) * edge_to_center} ${edge_to_center * (1 + cos(-twist))}" rpy="${-twist} 0 0"/>
        <geometry>
          <mesh filename="package://hebi_description/meshes/A-2039-02.stl"/>
        </geometry>
      </collision-->
    <!-- Approximate inertia as thin rod about x axis -->
    <inertial>
      <origin rpy="0 0 0" xyz="0.1375 0 0.02"/>
      <mass value="0.382"/>
      <inertia ixx="0.0" ixy="0.0" ixz="0.0" iyy="0.00240739583333" iyz="0.0" izz="0.00240739583333"/>
    </inertial>
  </link>
  <joint name="leg_1/shoulder_elbow/OUTPUT_JOINT" type="fixed">
    <parent link="leg_1/shoulder_elbow/INPUT_INTERFACE"/>
    <child link="leg_1/J3_elbow/INPUT_INTERFACE"/>
    <origin rpy="3.14159265359 0 0" xyz="0.275 -2.44929359829e-18 0.0"/>
  </joint>
  <link name="leg_1/J3_elbow/INPUT_INTERFACE">
    <visual>
      <origin rpy="0 0 0" xyz="0 0 0.0125"/>
      <geometry>
        <cylinder length="0.025" radius="0.035"/>
      </geometry>
      <material name="red">
        <color rgba=".82 0.06 0.06 1"/>
      </material>
    </visual>
    <collision>
      <origin rpy="0 0 0" xyz="0 0 0.0125"/>
      <geometry>
        <cylinder length="0.025" radius="0.035"/>
      </geometry>
    </collision>
    <inertial>
      <origin rpy="0 0 0" xyz="-0.0142 -0.0031 0.0165"/>
      <mass value="0.36"/>
      <inertia ixx="0.00015" ixy="0.0000341" ixz="0.0000118" iyy="0.000255" iyz="0.00000229" izz="0.000350"/>
    </inertial>
  </link>
  <joint name="leg_1/J3_elbow/X5_9" type="revolute">
    <parent link="leg_1/J3_elbow/INPUT_INTERFACE"/>
    <child link="leg_1/elbow_end/INPUT_INTERFACE"/>
    <origin rpy="0 0 0" xyz="0 0 0.031"/>
    <axis xyz="0 0 1"/>
    <limit effort="13.0" lower="0.785" upper="2.356" velocity="1.466"/>
    <dynamics damping="0.1" friction="0.1"/>
  </joint>
  <link name="leg_1/elbow_end/INPUT_INTERFACE">
    <!--visual>
        <origin xyz="0 0 0" rpy="0 0 0" />
        <geometry>
          <mesh filename="package://hebi_description/meshes/A-2038-02.stl"/>
        </geometry>
        <xacro:black_material/>
      </visual-->
    <visual>
      <origin rpy="0 1.57075 0" xyz="0.1375 0 0.02"/>
      <geometry>
        <cylinder length="0.2496" radius=".016"/>
      </geometry>
      <material name="silver">
        <color rgba="0.6 0.6 0.6 1"/>
      </material>
    </visual>
    <!--visual>
        <origin xyz="${extension} ${sin(-twist) * edge_to_center} ${edge_to_center * (1 + cos(-twist))}" rpy="${-twist} 0 0"/>
        <geometry>
          <mesh filename="package://hebi_description/meshes/A-2039-02.stl"/>
        </geometry>
        <xacro:black_material/>
      </visual-->
    <!--collision>
        <origin xyz="0 0 0" rpy="0 0 0" />
        <geometry>
          <mesh filename="package://hebi_description/meshes/A-2038-02.stl"/>
        </geometry>
      </collision-->
    <collision>
      <origin rpy="0 1.57075 0" xyz="0.1375 0 0.02"/>
      <geometry>
        <cylinder length="0.2496" radius=".016"/>
      </geometry>
    </collision>
    <!--collision>
        <origin xyz="${extension} ${sin(-twist) * edge_to_center} ${edge_to_center * (1 + cos(-twist))}" rpy="${-twist} 0 0"/>
        <geometry>
          <mesh filename="package://hebi_description/meshes/A-2039-02.stl"/>
        </geometry>
      </collision-->
    <!-- Approximate inertia as thin rod about x axis -->
    <inertial>
      <origin rpy="0 0 0" xyz="0.1375 0 0.02"/>
      <mass value="0.382"/>
      <inertia ixx="0.0" ixy="0.0" ixz="0.0" iyy="0.00240739583333" iyz="0.0" izz="0.00240739583333"/>
    </inertial>
  </link>
  <joint name="leg_1/elbow_end/OUTPUT_JOINT" type="fixed">
    <parent link="leg_1/elbow_end/INPUT_INTERFACE"/>
    <child link="leg_1/foot/INPUT_INTERFACE"/>
    <origin rpy="0 0 0" xyz="0.275 -0.0 0.04"/>
  </joint>
  <link name="leg_1/foot/INPUT_INTERFACE">
    <inertial>
      <origin rpy="0 0 0" xyz="0 0 -.02"/>
      <mass value="0.01"/>
      <inertia ixx="0.0001" ixy="0" ixz="0" iyy="0.0001" iyz="0" izz="0.0001"/>
    </inertial>
    <visual>
      <geometry>
        <sphere radius="0.02"/>
      </geometry>
      <origin rpy="0 0 0" xyz="0 0 -.02"/>
      <material name="black">
        <color rgba="0.1 0.1 0.1 1"/>
      </material>
    </visual>
    <collision>
      <geometry>
        <sphere radius="0.02"/>
      </geometry>
      <origin rpy="0 0 0" xyz="0 0 -.02"/>
    </collision>
  </link>
  <!-- use rubber bit for foot end link; necessary to provide output for HEBI components to attach to. -->
  <!-- connect leg to chassis -->
  <joint name="base_leg_2" type="fixed">
    <parent link="chassis"/>
    <child link="leg_2/J1_base/INPUT_INTERFACE"/>
    <origin rpy="0 0 0.0" xyz="0 0.1760    0.0095"/>
  </joint>
  <link name="leg_2/J1_base/INPUT_INTERFACE">
    <visual>
      <origin rpy="0 0 0" xyz="0 0 0.02"/>
      <geometry>
        <cylinder length="0.04" radius="0.035"/>
      </geometry>
      <material name="red">
        <color rgba=".82 0.06 0.06 1"/>
      </material>
    </visual>
    <collision>
      <origin rpy="0 0 0" xyz="0 0 0.02"/>
      <geometry>
        <cylinder length="0.04" radius="0.035"/>
      </geometry>
    </collision>
    <inertial>
      <origin rpy="0 0 0" xyz="-0.0145 -0.0031 0.0242"/>
      <mass value="0.48"/>
      <inertia ixx="0.000246" ixy="0.0000444" ixz="0.0000266" iyy="0.000380" iyz="0.00000422" izz="0.000463"/>
    </inertial>
  </link>
  <joint name="leg_2/J1_base/X8_9" type="revolute">
    <parent link="leg_2/J1_base/INPUT_INTERFACE"/>
    <child link="leg_2/shoulder_bracket/INPUT_INTERFACE"/>
    <origin rpy="0 0 0" xyz="0 0 0.045"/>
    <axis xyz="0 0 1"/>
    <limit effort="20" lower="0.523598775598" upper="2.61799387799" velocity="3.14"/>
    <dynamics damping="0.5" friction="0.5"/>
  </joint>
  <link name="leg_2/shoulder_bracket/INPUT_INTERFACE">
    <!-- REMOVED VISUAL AND COLLISION FOR SPEED
      <visual>
        <xacro:if value="${bracket_type.endswith('RightOutside')}">
          <origin xyz="0 0 0.005" rpy="${pi/2} 0 ${pi/2}"/>
        </xacro:if>
        <xacro:if value="${bracket_type.endswith('RightInside')}">
          <origin xyz="0 0 0.005" rpy="${pi/2} 0 ${-pi/2}"/>
        </xacro:if>
        <xacro:if value="${bracket_type.endswith('LeftOutside')}">
          <origin xyz="0 0 0.005" rpy="${pi/2} 0 ${-pi/2}"/>
        </xacro:if>
        <xacro:if value="${bracket_type.endswith('LeftInside')}">
          <origin xyz="0 0 0.005" rpy="${pi/2} 0 ${pi/2}"/>
        </xacro:if>
        <geometry>
          <mesh filename="PM-2149-01.stl" scale="0.001 0.001 0.001"/>
        </geometry>
        <xacro:black_material/>
      </visual>
      <visual>
        <xacro:if value="${bracket_type.endswith('RightOutside')}">
          <origin xyz="0 -.03 .04" rpy="${pi/2} 0 0"/>
        </xacro:if>
        <xacro:if value="${bracket_type.endswith('RightInside')}">
          <origin xyz="0 .03 .04" rpy="${pi/2} 0 0"/>
        </xacro:if>
        <xacro:if value="${bracket_type.endswith('LeftOutside')}">
          <origin xyz="0 -.03 .04" rpy="${pi/2} 0 0"/>
        </xacro:if>
        <xacro:if value="${bracket_type.endswith('LeftInside')}">
          <origin xyz="0 -.03 .04" rpy="${pi/2} 0 ${pi}"/>
        </xacro:if>
        <geometry>
          <xacro:if value="${bracket_type.startswith('X5HeavyRight') or bracket_type.startswith('R5HeavyRight')}">
            <mesh filename="PM-2150-01R.stl" scale="0.001 0.001 0.001"/>
          </xacro:if>
          <xacro:if value="${bracket_type.startswith('X5HeavyLeft') or bracket_type.startswith('R5HeavyLeft')}">
            <mesh filename="PM-2150-01L.stl" scale="0.001 0.001 0.001"/>
          </xacro:if>
        </geometry>
        <xacro:black_material/>
      </visual>

      <collision>
        <xacro:if value="${bracket_type.endswith('RightOutside')}">
          <origin xyz="0 0 0.005" rpy="${pi/2} 0 ${pi/2}"/>
        </xacro:if>
        <xacro:if value="${bracket_type.endswith('RightInside')}">
          <origin xyz="0 0 0.005" rpy="${pi/2} 0 ${-pi/2}"/>
        </xacro:if>
        <xacro:if value="${bracket_type.endswith('LeftOutside')}">
          <origin xyz="0 0 0.005" rpy="${pi/2} 0 ${-pi/2}"/>
        </xacro:if>
        <xacro:if value="${bracket_type.endswith('LeftInside')}">
          <origin xyz="0 0 0.005" rpy="${pi/2} 0 ${pi/2}"/>
        </xacro:if>
        <geometry>
          <mesh filename="PM-2149-01.stl" scale="0.001 0.001 0.001"/>
        </geometry>
      </collision>
      <collision>
        <xacro:if value="${bracket_type.endswith('RightOutside')}">
          <origin xyz="0 -.03 .04" rpy="${pi/2} 0 0"/>
        </xacro:if>
        <xacro:if value="${bracket_type.endswith('RightInside')}">
          <origin xyz="0 .03 .04" rpy="${pi/2} 0 0"/>
        </xacro:if>
        <xacro:if value="${bracket_type.endswith('LeftOutside')}">
          <origin xyz="0 .03 .04" rpy="${pi/2} 0 ${pi}"/>
        </xacro:if>
        <xacro:if value="${bracket_type.endswith('LeftInside')}">
          <origin xyz="0 -.03 .04" rpy="${pi/2} 0 ${pi}"/>
        </xacro:if>
        <geometry>
          <xacro:if value="${bracket_type.startswith('X5HeavyRight') or bracket_type.startswith('R5HeavyRight')}">
            <mesh filename="PM-2150-01R.stl" scale="0.001 0.001 0.001"/>
          </xacro:if>
          <xacro:if value="${bracket_type.startswith('X5HeavyLeft') or bracket_type.startswith('R5HeavyLeft')}">
            <mesh filename="PM-2150-01L.stl" scale="0.001 0.001 0.001"/>
          </xacro:if>
        </geometry>
      </collision>
      -->
    <!-- NOTE: inertia is just modelled as small sphere, and could be improved. -->
    <inertial>
      <origin rpy="0 0 0" xyz="0 0.01125 .0275"/>
      <mass value="0.215"/>
      <inertia ixx="0.0003096" ixy="0.0" ixz="0.0" iyy="0.0003096" iyz="0.0" izz="0.0003096"/>
    </inertial>
  </link>
  <joint name="leg_2/shoulder_bracket/OUTPUT_INTERFACE" type="fixed">
    <parent link="leg_2/shoulder_bracket/INPUT_INTERFACE"/>
    <child link="leg_2/J2_shoulder/INPUT_INTERFACE"/>
    <origin rpy="1.57079632679 0 0" xyz="0 .0225 .055"/>
  </joint>
  <link name="leg_2/J2_shoulder/INPUT_INTERFACE">
    <visual>
      <origin rpy="0 0 0" xyz="0 0 0.02"/>
      <geometry>
        <cylinder length="0.04" radius="0.035"/>
      </geometry>
      <material name="red">
        <color rgba=".82 0.06 0.06 1"/>
      </material>
    </visual>
    <collision>
      <origin rpy="0 0 0" xyz="0 0 0.02"/>
      <geometry>
        <cylinder length="0.04" radius="0.035"/>
      </geometry>
    </collision>
    <inertial>
      <origin rpy="0 0 0" xyz="-0.0145 -0.0031 0.0242"/>
      <mass value="0.5"/>
      <inertia ixx="0.000246" ixy="0.0000444" ixz="0.0000266" iyy="0.000380" iyz="0.00000422" izz="0.000463"/>
    </inertial>
  </link>
  <joint name="leg_2/J2_shoulder/X8_16" type="revolute">
    <parent link="leg_2/J2_shoulder/INPUT_INTERFACE"/>
    <child link="leg_2/shoulder_elbow/INPUT_INTERFACE"/>
    <origin rpy="0 0 0" xyz="0 0 0.045"/>
    <axis xyz="0 0 1"/>
    <limit effort="38" lower="-0.785398163397" upper="0.785398163397" velocity="1.571"/>
    <dynamics damping="0.5" friction="0.5"/>
  </joint>
  <link name="leg_2/shoulder_elbow/INPUT_INTERFACE">
    <!--visual>
        <origin xyz="0 0 0" rpy="0 0 0" />
        <geometry>
          <mesh filename="package://hebi_description/meshes/A-2038-02.stl"/>
        </geometry>
        <xacro:black_material/>
      </visual-->
    <visual>
      <origin rpy="0 1.57075 0" xyz="0.1375 0 0.02"/>
      <geometry>
        <cylinder length="0.2496" radius=".016"/>
      </geometry>
      <material name="silver">
        <color rgba="0.6 0.6 0.6 1"/>
      </material>
    </visual>
    <!--visual>
        <origin xyz="${extension} ${sin(-twist) * edge_to_center} ${edge_to_center * (1 + cos(-twist))}" rpy="${-twist} 0 0"/>
        <geometry>
          <mesh filename="package://hebi_description/meshes/A-2039-02.stl"/>
        </geometry>
        <xacro:black_material/>
      </visual-->
    <!--collision>
        <origin xyz="0 0 0" rpy="0 0 0" />
        <geometry>
          <mesh filename="package://hebi_description/meshes/A-2038-02.stl"/>
        </geometry>
      </collision-->
    <collision>
      <origin rpy="0 1.57075 0" xyz="0.1375 0 0.02"/>
      <geometry>
        <cylinder length="0.2496" radius=".016"/>
      </geometry>
    </collision>
    <!--collision>
        <origin xyz="${extension} ${sin(-twist) * edge_to_center} ${edge_to_center * (1 + cos(-twist))}" rpy="${-twist} 0 0"/>
        <geometry>
          <mesh filename="package://hebi_description/meshes/A-2039-02.stl"/>
        </geometry>
      </collision-->
    <!-- Approximate inertia as thin rod about x axis -->
    <inertial>
      <origin rpy="0 0 0" xyz="0.1375 0 0.02"/>
      <mass value="0.382"/>
      <inertia ixx="0.0" ixy="0.0" ixz="0.0" iyy="0.00240739583333" iyz="0.0" izz="0.00240739583333"/>
    </inertial>
  </link>
  <joint name="leg_2/shoulder_elbow/OUTPUT_JOINT" type="fixed">
    <parent link="leg_2/shoulder_elbow/INPUT_INTERFACE"/>
    <child link="leg_2/J3_elbow/INPUT_INTERFACE"/>
    <origin rpy="3.14159265359 0 0" xyz="0.275 -2.44929359829e-18 0.0"/>
  </joint>
  <link name="leg_2/J3_elbow/INPUT_INTERFACE">
    <visual>
      <origin rpy="0 0 0" xyz="0 0 0.0125"/>
      <geometry>
        <cylinder length="0.025" radius="0.035"/>
      </geometry>
      <material name="red">
        <color rgba=".82 0.06 0.06 1"/>
      </material>
    </visual>
    <collision>
      <origin rpy="0 0 0" xyz="0 0 0.0125"/>
      <geometry>
        <cylinder length="0.025" radius="0.035"/>
      </geometry>
    </collision>
    <inertial>
      <origin rpy="0 0 0" xyz="-0.0142 -0.0031 0.0165"/>
      <mass value="0.36"/>
      <inertia ixx="0.00015" ixy="0.0000341" ixz="0.0000118" iyy="0.000255" iyz="0.00000229" izz="0.000350"/>
    </inertial>
  </link>
  <joint name="leg_2/J3_elbow/X5_9" type="revolute">
    <parent link="leg_2/J3_elbow/INPUT_INTERFACE"/>
    <child link="leg_2/elbow_end/INPUT_INTERFACE"/>
    <origin rpy="0 0 0" xyz="0 0 0.031"/>
    <axis xyz="0 0 1"/>
    <limit effort="13.0" lower="0.785" upper="2.356" velocity="1.466"/>
    <dynamics damping="0.1" friction="0.1"/>
  </joint>
  <link name="leg_2/elbow_end/INPUT_INTERFACE">
    <!--visual>
        <origin xyz="0 0 0" rpy="0 0 0" />
        <geometry>
          <mesh filename="package://hebi_description/meshes/A-2038-02.stl"/>
        </geometry>
        <xacro:black_material/>
      </visual-->
    <visual>
      <origin rpy="0 1.57075 0" xyz="0.1375 0 0.02"/>
      <geometry>
        <cylinder length="0.2496" radius=".016"/>
      </geometry>
      <material name="silver">
        <color rgba="0.6 0.6 0.6 1"/>
      </material>
    </visual>
    <!--visual>
        <origin xyz="${extension} ${sin(-twist) * edge_to_center} ${edge_to_center * (1 + cos(-twist))}" rpy="${-twist} 0 0"/>
        <geometry>
          <mesh filename="package://hebi_description/meshes/A-2039-02.stl"/>
        </geometry>
        <xacro:black_material/>
      </visual-->
    <!--collision>
        <origin xyz="0 0 0" rpy="0 0 0" />
        <geometry>
          <mesh filename="package://hebi_description/meshes/A-2038-02.stl"/>
        </geometry>
      </collision-->
    <collision>
      <origin rpy="0 1.57075 0" xyz="0.1375 0 0.02"/>
      <geometry>
        <cylinder length="0.2496" radius=".016"/>
      </geometry>
    </collision>
    <!--collision>
        <origin xyz="${extension} ${sin(-twist) * edge_to_center} ${edge_to_center * (1 + cos(-twist))}" rpy="${-twist} 0 0"/>
        <geometry>
          <mesh filename="package://hebi_description/meshes/A-2039-02.stl"/>
        </geometry>
      </collision-->
    <!-- Approximate inertia as thin rod about x axis -->
    <inertial>
      <origin rpy="0 0 0" xyz="0.1375 0 0.02"/>
      <mass value="0.382"/>
      <inertia ixx="0.0" ixy="0.0" ixz="0.0" iyy="0.00240739583333" iyz="0.0" izz="0.00240739583333"/>
    </inertial>
  </link>
  <joint name="leg_2/elbow_end/OUTPUT_JOINT" type="fixed">
    <parent link="leg_2/elbow_end/INPUT_INTERFACE"/>
    <child link="leg_2/foot/INPUT_INTERFACE"/>
    <origin rpy="0 0 0" xyz="0.275 -0.0 0.04"/>
  </joint>
  <link name="leg_2/foot/INPUT_INTERFACE">
    <inertial>
      <origin rpy="0 0 0" xyz="0 0 -.02"/>
      <mass value="0.01"/>
      <inertia ixx="0.0001" ixy="0" ixz="0" iyy="0.0001" iyz="0" izz="0.0001"/>
    </inertial>
    <visual>
      <geometry>
        <sphere radius="0.02"/>
      </geometry>
      <origin rpy="0 0 0" xyz="0 0 -.02"/>
      <material name="black">
        <color rgba="0.1 0.1 0.1 1"/>
      </material>
    </visual>
    <collision>
      <geometry>
        <sphere radius="0.02"/>
      </geometry>
      <origin rpy="0 0 0" xyz="0 0 -.02"/>
    </collision>
  </link>
  <!-- use rubber bit for foot end link; necessary to provide output for HEBI components to attach to. -->
  <!-- No limb at port 3-->
  <!-- No limb at port 4-->
  <!-- connect leg to chassis -->
  <joint name="base_leg_5" type="fixed">
    <parent link="chassis"/>
    <child link="leg_5/J1_base/INPUT_INTERFACE"/>
    <origin rpy="0 0 3.14159265359" xyz="0 -0.1760  0.0095"/>
  </joint>
  <link name="leg_5/J1_base/INPUT_INTERFACE">
    <visual>
      <origin rpy="0 0 0" xyz="0 0 0.02"/>
      <geometry>
        <cylinder length="0.04" radius="0.035"/>
      </geometry>
      <material name="red">
        <color rgba=".82 0.06 0.06 1"/>
      </material>
    </visual>
    <collision>
      <origin rpy="0 0 0" xyz="0 0 0.02"/>
      <geometry>
        <cylinder length="0.04" radius="0.035"/>
      </geometry>
    </collision>
    <inertial>
      <origin rpy="0 0 0" xyz="-0.0145 -0.0031 0.0242"/>
      <mass value="0.48"/>
      <inertia ixx="0.000246" ixy="0.0000444" ixz="0.0000266" iyy="0.000380" iyz="0.00000422" izz="0.000463"/>
    </inertial>
  </link>
  <joint name="leg_5/J1_base/X8_9" type="revolute">
    <parent link="leg_5/J1_base/INPUT_INTERFACE"/>
    <child link="leg_5/shoulder_bracket/INPUT_INTERFACE"/>
    <origin rpy="0 0 0" xyz="0 0 0.045"/>
    <axis xyz="0 0 1"/>
    <limit effort="20" lower="0.523598775598" upper="2.61799387799" velocity="3.14"/>
    <dynamics damping="0.5" friction="0.5"/>
  </joint>
  <link name="leg_5/shoulder_bracket/INPUT_INTERFACE">
    <!-- REMOVED VISUAL AND COLLISION FOR SPEED
      <visual>
        <xacro:if value="${bracket_type.endswith('RightOutside')}">
          <origin xyz="0 0 0.005" rpy="${pi/2} 0 ${pi/2}"/>
        </xacro:if>
        <xacro:if value="${bracket_type.endswith('RightInside')}">
          <origin xyz="0 0 0.005" rpy="${pi/2} 0 ${-pi/2}"/>
        </xacro:if>
        <xacro:if value="${bracket_type.endswith('LeftOutside')}">
          <origin xyz="0 0 0.005" rpy="${pi/2} 0 ${-pi/2}"/>
        </xacro:if>
        <xacro:if value="${bracket_type.endswith('LeftInside')}">
          <origin xyz="0 0 0.005" rpy="${pi/2} 0 ${pi/2}"/>
        </xacro:if>
        <geometry>
          <mesh filename="PM-2149-01.stl" scale="0.001 0.001 0.001"/>
        </geometry>
        <xacro:black_material/>
      </visual>
      <visual>
        <xacro:if value="${bracket_type.endswith('RightOutside')}">
          <origin xyz="0 -.03 .04" rpy="${pi/2} 0 0"/>
        </xacro:if>
        <xacro:if value="${bracket_type.endswith('RightInside')}">
          <origin xyz="0 .03 .04" rpy="${pi/2} 0 0"/>
        </xacro:if>
        <xacro:if value="${bracket_type.endswith('LeftOutside')}">
          <origin xyz="0 -.03 .04" rpy="${pi/2} 0 0"/>
        </xacro:if>
        <xacro:if value="${bracket_type.endswith('LeftInside')}">
          <origin xyz="0 -.03 .04" rpy="${pi/2} 0 ${pi}"/>
        </xacro:if>
        <geometry>
          <xacro:if value="${bracket_type.startswith('X5HeavyRight') or bracket_type.startswith('R5HeavyRight')}">
            <mesh filename="PM-2150-01R.stl" scale="0.001 0.001 0.001"/>
          </xacro:if>
          <xacro:if value="${bracket_type.startswith('X5HeavyLeft') or bracket_type.startswith('R5HeavyLeft')}">
            <mesh filename="PM-2150-01L.stl" scale="0.001 0.001 0.001"/>
          </xacro:if>
        </geometry>
        <xacro:black_material/>
      </visual>

      <collision>
        <xacro:if value="${bracket_type.endswith('RightOutside')}">
          <origin xyz="0 0 0.005" rpy="${pi/2} 0 ${pi/2}"/>
        </xacro:if>
        <xacro:if value="${bracket_type.endswith('RightInside')}">
          <origin xyz="0 0 0.005" rpy="${pi/2} 0 ${-pi/2}"/>
        </xacro:if>
        <xacro:if value="${bracket_type.endswith('LeftOutside')}">
          <origin xyz="0 0 0.005" rpy="${pi/2} 0 ${-pi/2}"/>
        </xacro:if>
        <xacro:if value="${bracket_type.endswith('LeftInside')}">
          <origin xyz="0 0 0.005" rpy="${pi/2} 0 ${pi/2}"/>
        </xacro:if>
        <geometry>
          <mesh filename="PM-2149-01.stl" scale="0.001 0.001 0.001"/>
        </geometry>
      </collision>
      <collision>
        <xacro:if value="${bracket_type.endswith('RightOutside')}">
          <origin xyz="0 -.03 .04" rpy="${pi/2} 0 0"/>
        </xacro:if>
        <xacro:if value="${bracket_type.endswith('RightInside')}">
          <origin xyz="0 .03 .04" rpy="${pi/2} 0 0"/>
        </xacro:if>
        <xacro:if value="${bracket_type.endswith('LeftOutside')}">
          <origin xyz="0 .03 .04" rpy="${pi/2} 0 ${pi}"/>
        </xacro:if>
        <xacro:if value="${bracket_type.endswith('LeftInside')}">
          <origin xyz="0 -.03 .04" rpy="${pi/2} 0 ${pi}"/>
        </xacro:if>
        <geometry>
          <xacro:if value="${bracket_type.startswith('X5HeavyRight') or bracket_type.startswith('R5HeavyRight')}">
            <mesh filename="PM-2150-01R.stl" scale="0.001 0.001 0.001"/>
          </xacro:if>
          <xacro:if value="${bracket_type.startswith('X5HeavyLeft') or bracket_type.startswith('R5HeavyLeft')}">
            <mesh filename="PM-2150-01L.stl" scale="0.001 0.001 0.001"/>
          </xacro:if>
        </geometry>
      </collision>
      -->
    <!-- NOTE: inertia is just modelled as small sphere, and could be improved. -->
    <inertial>
      <origin rpy="0 0 0" xyz="0 0.01125 .0275"/>
      <mass value="0.215"/>
      <inertia ixx="0.0003096" ixy="0.0" ixz="0.0" iyy="0.0003096" iyz="0.0" izz="0.0003096"/>
    </inertial>
  </link>
  <joint name="leg_5/shoulder_bracket/OUTPUT_INTERFACE" type="fixed">
    <parent link="leg_5/shoulder_bracket/INPUT_INTERFACE"/>
    <child link="leg_5/J2_shoulder/INPUT_INTERFACE"/>
    <origin rpy="1.57079632679 0 0" xyz="0 .0225 .055"/>
  </joint>
  <link name="leg_5/J2_shoulder/INPUT_INTERFACE">
    <visual>
      <origin rpy="0 0 0" xyz="0 0 0.02"/>
      <geometry>
        <cylinder length="0.04" radius="0.035"/>
      </geometry>
      <material name="red">
        <color rgba=".82 0.06 0.06 1"/>
      </material>
    </visual>
    <collision>
      <origin rpy="0 0 0" xyz="0 0 0.02"/>
      <geometry>
        <cylinder length="0.04" radius="0.035"/>
      </geometry>
    </collision>
    <inertial>
      <origin rpy="0 0 0" xyz="-0.0145 -0.0031 0.0242"/>
      <mass value="0.5"/>
      <inertia ixx="0.000246" ixy="0.0000444" ixz="0.0000266" iyy="0.000380" iyz="0.00000422" izz="0.000463"/>
    </inertial>
  </link>
  <joint name="leg_5/J2_shoulder/X8_16" type="revolute">
    <parent link="leg_5/J2_shoulder/INPUT_INTERFACE"/>
    <child link="leg_5/shoulder_elbow/INPUT_INTERFACE"/>
    <origin rpy="0 0 0" xyz="0 0 0.045"/>
    <axis xyz="0 0 1"/>
    <limit effort="38" lower="-0.785398163397" upper="0.785398163397" velocity="1.571"/>
    <dynamics damping="0.5" friction="0.5"/>
  </joint>
  <link name="leg_5/shoulder_elbow/INPUT_INTERFACE">
    <!--visual>
        <origin xyz="0 0 0" rpy="0 0 0" />
        <geometry>
          <mesh filename="package://hebi_description/meshes/A-2038-02.stl"/>
        </geometry>
        <xacro:black_material/>
      </visual-->
    <visual>
      <origin rpy="0 1.57075 0" xyz="0.1375 0 0.02"/>
      <geometry>
        <cylinder length="0.2496" radius=".016"/>
      </geometry>
      <material name="silver">
        <color rgba="0.6 0.6 0.6 1"/>
      </material>
    </visual>
    <!--visual>
        <origin xyz="${extension} ${sin(-twist) * edge_to_center} ${edge_to_center * (1 + cos(-twist))}" rpy="${-twist} 0 0"/>
        <geometry>
          <mesh filename="package://hebi_description/meshes/A-2039-02.stl"/>
        </geometry>
        <xacro:black_material/>
      </visual-->
    <!--collision>
        <origin xyz="0 0 0" rpy="0 0 0" />
        <geometry>
          <mesh filename="package://hebi_description/meshes/A-2038-02.stl"/>
        </geometry>
      </collision-->
    <collision>
      <origin rpy="0 1.57075 0" xyz="0.1375 0 0.02"/>
      <geometry>
        <cylinder length="0.2496" radius=".016"/>
      </geometry>
    </collision>
    <!--collision>
        <origin xyz="${extension} ${sin(-twist) * edge_to_center} ${edge_to_center * (1 + cos(-twist))}" rpy="${-twist} 0 0"/>
        <geometry>
          <mesh filename="package://hebi_description/meshes/A-2039-02.stl"/>
        </geometry>
      </collision-->
    <!-- Approximate inertia as thin rod about x axis -->
    <inertial>
      <origin rpy="0 0 0" xyz="0.1375 0 0.02"/>
      <mass value="0.382"/>
      <inertia ixx="0.0" ixy="0.0" ixz="0.0" iyy="0.00240739583333" iyz="0.0" izz="0.00240739583333"/>
    </inertial>
  </link>
  <joint name="leg_5/shoulder_elbow/OUTPUT_JOINT" type="fixed">
    <parent link="leg_5/shoulder_elbow/INPUT_INTERFACE"/>
    <child link="leg_5/J3_elbow/INPUT_INTERFACE"/>
    <origin rpy="3.14159265359 0 0" xyz="0.275 -2.44929359829e-18 0.0"/>
  </joint>
  <link name="leg_5/J3_elbow/INPUT_INTERFACE">
    <visual>
      <origin rpy="0 0 0" xyz="0 0 0.0125"/>
      <geometry>
        <cylinder length="0.025" radius="0.035"/>
      </geometry>
      <material name="red">
        <color rgba=".82 0.06 0.06 1"/>
      </material>
    </visual>
    <collision>
      <origin rpy="0 0 0" xyz="0 0 0.0125"/>
      <geometry>
        <cylinder length="0.025" radius="0.035"/>
      </geometry>
    </collision>
    <inertial>
      <origin rpy="0 0 0" xyz="-0.0142 -0.0031 0.0165"/>
      <mass value="0.36"/>
      <inertia ixx="0.00015" ixy="0.0000341" ixz="0.0000118" iyy="0.000255" iyz="0.00000229" izz="0.000350"/>
    </inertial>
  </link>
  <joint name="leg_5/J3_elbow/X5_9" type="revolute">
    <parent link="leg_5/J3_elbow/INPUT_INTERFACE"/>
    <child link="leg_5/elbow_end/INPUT_INTERFACE"/>
    <origin rpy="0 0 0" xyz="0 0 0.031"/>
    <axis xyz="0 0 1"/>
    <limit effort="13.0" lower="0.785" upper="2.356" velocity="1.466"/>
    <dynamics damping="0.1" friction="0.1"/>
  </joint>
  <link name="leg_5/elbow_end/INPUT_INTERFACE">
    <!--visual>
        <origin xyz="0 0 0" rpy="0 0 0" />
        <geometry>
          <mesh filename="package://hebi_description/meshes/A-2038-02.stl"/>
        </geometry>
        <xacro:black_material/>
      </visual-->
    <visual>
      <origin rpy="0 1.57075 0" xyz="0.1375 0 0.02"/>
      <geometry>
        <cylinder length="0.2496" radius=".016"/>
      </geometry>
      <material name="silver">
        <color rgba="0.6 0.6 0.6 1"/>
      </material>
    </visual>
    <!--visual>
        <origin xyz="${extension} ${sin(-twist) * edge_to_center} ${edge_to_center * (1 + cos(-twist))}" rpy="${-twist} 0 0"/>
        <geometry>
          <mesh filename="package://hebi_description/meshes/A-2039-02.stl"/>
        </geometry>
        <xacro:black_material/>
      </visual-->
    <!--collision>
        <origin xyz="0 0 0" rpy="0 0 0" />
        <geometry>
          <mesh filename="package://hebi_description/meshes/A-2038-02.stl"/>
        </geometry>
      </collision-->
    <collision>
      <origin rpy="0 1.57075 0" xyz="0.1375 0 0.02"/>
      <geometry>
        <cylinder length="0.2496" radius=".016"/>
      </geometry>
    </collision>
    <!--collision>
        <origin xyz="${extension} ${sin(-twist) * edge_to_center} ${edge_to_center * (1 + cos(-twist))}" rpy="${-twist} 0 0"/>
        <geometry>
          <mesh filename="package://hebi_description/meshes/A-2039-02.stl"/>
        </geometry>
      </collision-->
    <!-- Approximate inertia as thin rod about x axis -->
    <inertial>
      <origin rpy="0 0 0" xyz="0.1375 0 0.02"/>
      <mass value="0.382"/>
      <inertia ixx="0.0" ixy="0.0" ixz="0.0" iyy="0.00240739583333" iyz="0.0" izz="0.00240739583333"/>
    </inertial>
  </link>
  <joint name="leg_5/elbow_end/OUTPUT_JOINT" type="fixed">
    <parent link="leg_5/elbow_end/INPUT_INTERFACE"/>
    <child link="leg_5/foot/INPUT_INTERFACE"/>
    <origin rpy="0 0 0" xyz="0.275 -0.0 0.04"/>
  </joint>
  <link name="leg_5/foot/INPUT_INTERFACE">
    <inertial>
      <origin rpy="0 0 0" xyz="0 0 -.02"/>
      <mass value="0.01"/>
      <inertia ixx="0.0001" ixy="0" ixz="0" iyy="0.0001" iyz="0" izz="0.0001"/>
    </inertial>
    <visual>
      <geometry>
        <sphere radius="0.02"/>
      </geometry>
      <origin rpy="0 0 0" xyz="0 0 -.02"/>
      <material name="black">
        <color rgba="0.1 0.1 0.1 1"/>
      </material>
    </visual>
    <collision>
      <geometry>
        <sphere radius="0.02"/>
      </geometry>
      <origin rpy="0 0 0" xyz="0 0 -.02"/>
    </collision>
  </link>
  <!-- use rubber bit for foot end link; necessary to provide output for HEBI components to attach to. -->
  <!-- connect leg to chassis -->
  <joint name="base_leg_6" type="fixed">
    <parent link="chassis"/>
    <child link="leg_6/J1_base/INPUT_INTERFACE"/>
    <origin rpy="0 0 4.18879020479" xyz="0.1524 -0.0880 0.0095"/>
  </joint>
  <link name="leg_6/J1_base/INPUT_INTERFACE">
    <visual>
      <origin rpy="0 0 0" xyz="0 0 0.02"/>
      <geometry>
        <cylinder length="0.04" radius="0.035"/>
      </geometry>
      <material name="red">
        <color rgba=".82 0.06 0.06 1"/>
      </material>
    </visual>
    <collision>
      <origin rpy="0 0 0" xyz="0 0 0.02"/>
      <geometry>
        <cylinder length="0.04" radius="0.035"/>
      </geometry>
    </collision>
    <inertial>
      <origin rpy="0 0 0" xyz="-0.0145 -0.0031 0.0242"/>
      <mass value="0.48"/>
      <inertia ixx="0.000246" ixy="0.0000444" ixz="0.0000266" iyy="0.000380" iyz="0.00000422" izz="0.000463"/>
    </inertial>
  </link>
  <joint name="leg_6/J1_base/X8_9" type="revolute">
    <parent link="leg_6/J1_base/INPUT_INTERFACE"/>
    <child link="leg_6/shoulder_bracket/INPUT_INTERFACE"/>
    <origin rpy="0 0 0" xyz="0 0 0.045"/>
    <axis xyz="0 0 1"/>
    <limit effort="20" lower="0.523598775598" upper="2.61799387799" velocity="3.14"/>
    <dynamics damping="0.5" friction="0.5"/>
  </joint>
  <link name="leg_6/shoulder_bracket/INPUT_INTERFACE">
    <!-- REMOVED VISUAL AND COLLISION FOR SPEED
      <visual>
        <xacro:if value="${bracket_type.endswith('RightOutside')}">
          <origin xyz="0 0 0.005" rpy="${pi/2} 0 ${pi/2}"/>
        </xacro:if>
        <xacro:if value="${bracket_type.endswith('RightInside')}">
          <origin xyz="0 0 0.005" rpy="${pi/2} 0 ${-pi/2}"/>
        </xacro:if>
        <xacro:if value="${bracket_type.endswith('LeftOutside')}">
          <origin xyz="0 0 0.005" rpy="${pi/2} 0 ${-pi/2}"/>
        </xacro:if>
        <xacro:if value="${bracket_type.endswith('LeftInside')}">
          <origin xyz="0 0 0.005" rpy="${pi/2} 0 ${pi/2}"/>
        </xacro:if>
        <geometry>
          <mesh filename="PM-2149-01.stl" scale="0.001 0.001 0.001"/>
        </geometry>
        <xacro:black_material/>
      </visual>
      <visual>
        <xacro:if value="${bracket_type.endswith('RightOutside')}">
          <origin xyz="0 -.03 .04" rpy="${pi/2} 0 0"/>
        </xacro:if>
        <xacro:if value="${bracket_type.endswith('RightInside')}">
          <origin xyz="0 .03 .04" rpy="${pi/2} 0 0"/>
        </xacro:if>
        <xacro:if value="${bracket_type.endswith('LeftOutside')}">
          <origin xyz="0 -.03 .04" rpy="${pi/2} 0 0"/>
        </xacro:if>
        <xacro:if value="${bracket_type.endswith('LeftInside')}">
          <origin xyz="0 -.03 .04" rpy="${pi/2} 0 ${pi}"/>
        </xacro:if>
        <geometry>
          <xacro:if value="${bracket_type.startswith('X5HeavyRight') or bracket_type.startswith('R5HeavyRight')}">
            <mesh filename="PM-2150-01R.stl" scale="0.001 0.001 0.001"/>
          </xacro:if>
          <xacro:if value="${bracket_type.startswith('X5HeavyLeft') or bracket_type.startswith('R5HeavyLeft')}">
            <mesh filename="PM-2150-01L.stl" scale="0.001 0.001 0.001"/>
          </xacro:if>
        </geometry>
        <xacro:black_material/>
      </visual>

      <collision>
        <xacro:if value="${bracket_type.endswith('RightOutside')}">
          <origin xyz="0 0 0.005" rpy="${pi/2} 0 ${pi/2}"/>
        </xacro:if>
        <xacro:if value="${bracket_type.endswith('RightInside')}">
          <origin xyz="0 0 0.005" rpy="${pi/2} 0 ${-pi/2}"/>
        </xacro:if>
        <xacro:if value="${bracket_type.endswith('LeftOutside')}">
          <origin xyz="0 0 0.005" rpy="${pi/2} 0 ${-pi/2}"/>
        </xacro:if>
        <xacro:if value="${bracket_type.endswith('LeftInside')}">
          <origin xyz="0 0 0.005" rpy="${pi/2} 0 ${pi/2}"/>
        </xacro:if>
        <geometry>
          <mesh filename="PM-2149-01.stl" scale="0.001 0.001 0.001"/>
        </geometry>
      </collision>
      <collision>
        <xacro:if value="${bracket_type.endswith('RightOutside')}">
          <origin xyz="0 -.03 .04" rpy="${pi/2} 0 0"/>
        </xacro:if>
        <xacro:if value="${bracket_type.endswith('RightInside')}">
          <origin xyz="0 .03 .04" rpy="${pi/2} 0 0"/>
        </xacro:if>
        <xacro:if value="${bracket_type.endswith('LeftOutside')}">
          <origin xyz="0 .03 .04" rpy="${pi/2} 0 ${pi}"/>
        </xacro:if>
        <xacro:if value="${bracket_type.endswith('LeftInside')}">
          <origin xyz="0 -.03 .04" rpy="${pi/2} 0 ${pi}"/>
        </xacro:if>
        <geometry>
          <xacro:if value="${bracket_type.startswith('X5HeavyRight') or bracket_type.startswith('R5HeavyRight')}">
            <mesh filename="PM-2150-01R.stl" scale="0.001 0.001 0.001"/>
          </xacro:if>
          <xacro:if value="${bracket_type.startswith('X5HeavyLeft') or bracket_type.startswith('R5HeavyLeft')}">
            <mesh filename="PM-2150-01L.stl" scale="0.001 0.001 0.001"/>
          </xacro:if>
        </geometry>
      </collision>
      -->
    <!-- NOTE: inertia is just modelled as small sphere, and could be improved. -->
    <inertial>
      <origin rpy="0 0 0" xyz="0 0.01125 .0275"/>
      <mass value="0.215"/>
      <inertia ixx="0.0003096" ixy="0.0" ixz="0.0" iyy="0.0003096" iyz="0.0" izz="0.0003096"/>
    </inertial>
  </link>
  <joint name="leg_6/shoulder_bracket/OUTPUT_INTERFACE" type="fixed">
    <parent link="leg_6/shoulder_bracket/INPUT_INTERFACE"/>
    <child link="leg_6/J2_shoulder/INPUT_INTERFACE"/>
    <origin rpy="1.57079632679 0 0" xyz="0 .0225 .055"/>
  </joint>
  <link name="leg_6/J2_shoulder/INPUT_INTERFACE">
    <visual>
      <origin rpy="0 0 0" xyz="0 0 0.02"/>
      <geometry>
        <cylinder length="0.04" radius="0.035"/>
      </geometry>
      <material name="red">
        <color rgba=".82 0.06 0.06 1"/>
      </material>
    </visual>
    <collision>
      <origin rpy="0 0 0" xyz="0 0 0.02"/>
      <geometry>
        <cylinder length="0.04" radius="0.035"/>
      </geometry>
    </collision>
    <inertial>
      <origin rpy="0 0 0" xyz="-0.0145 -0.0031 0.0242"/>
      <mass value="0.5"/>
      <inertia ixx="0.000246" ixy="0.0000444" ixz="0.0000266" iyy="0.000380" iyz="0.00000422" izz="0.000463"/>
    </inertial>
  </link>
  <joint name="leg_6/J2_shoulder/X8_16" type="revolute">
    <parent link="leg_6/J2_shoulder/INPUT_INTERFACE"/>
    <child link="leg_6/shoulder_elbow/INPUT_INTERFACE"/>
    <origin rpy="0 0 0" xyz="0 0 0.045"/>
    <axis xyz="0 0 1"/>
    <limit effort="38" lower="-0.785398163397" upper="0.785398163397" velocity="1.571"/>
    <dynamics damping="0.5" friction="0.5"/>
  </joint>
  <link name="leg_6/shoulder_elbow/INPUT_INTERFACE">
    <!--visual>
        <origin xyz="0 0 0" rpy="0 0 0" />
        <geometry>
          <mesh filename="package://hebi_description/meshes/A-2038-02.stl"/>
        </geometry>
        <xacro:black_material/>
      </visual-->
    <visual>
      <origin rpy="0 1.57075 0" xyz="0.1375 0 0.02"/>
      <geometry>
        <cylinder length="0.2496" radius=".016"/>
      </geometry>
      <material name="silver">
        <color rgba="0.6 0.6 0.6 1"/>
      </material>
    </visual>
    <!--visual>
        <origin xyz="${extension} ${sin(-twist) * edge_to_center} ${edge_to_center * (1 + cos(-twist))}" rpy="${-twist} 0 0"/>
        <geometry>
          <mesh filename="package://hebi_description/meshes/A-2039-02.stl"/>
        </geometry>
        <xacro:black_material/>
      </visual-->
    <!--collision>
        <origin xyz="0 0 0" rpy="0 0 0" />
        <geometry>
          <mesh filename="package://hebi_description/meshes/A-2038-02.stl"/>
        </geometry>
      </collision-->
    <collision>
      <origin rpy="0 1.57075 0" xyz="0.1375 0 0.02"/>
      <geometry>
        <cylinder length="0.2496" radius=".016"/>
      </geometry>
    </collision>
    <!--collision>
        <origin xyz="${extension} ${sin(-twist) * edge_to_center} ${edge_to_center * (1 + cos(-twist))}" rpy="${-twist} 0 0"/>
        <geometry>
          <mesh filename="package://hebi_description/meshes/A-2039-02.stl"/>
        </geometry>
      </collision-->
    <!-- Approximate inertia as thin rod about x axis -->
    <inertial>
      <origin rpy="0 0 0" xyz="0.1375 0 0.02"/>
      <mass value="0.382"/>
      <inertia ixx="0.0" ixy="0.0" ixz="0.0" iyy="0.00240739583333" iyz="0.0" izz="0.00240739583333"/>
    </inertial>
  </link>
  <joint name="leg_6/shoulder_elbow/OUTPUT_JOINT" type="fixed">
    <parent link="leg_6/shoulder_elbow/INPUT_INTERFACE"/>
    <child link="leg_6/J3_elbow/INPUT_INTERFACE"/>
    <origin rpy="3.14159265359 0 0" xyz="0.275 -2.44929359829e-18 0.0"/>
  </joint>
  <link name="leg_6/J3_elbow/INPUT_INTERFACE">
    <visual>
      <origin rpy="0 0 0" xyz="0 0 0.0125"/>
      <geometry>
        <cylinder length="0.025" radius="0.035"/>
      </geometry>
      <material name="red">
        <color rgba=".82 0.06 0.06 1"/>
      </material>
    </visual>
    <collision>
      <origin rpy="0 0 0" xyz="0 0 0.0125"/>
      <geometry>
        <cylinder length="0.025" radius="0.035"/>
      </geometry>
    </collision>
    <inertial>
      <origin rpy="0 0 0" xyz="-0.0142 -0.0031 0.0165"/>
      <mass value="0.36"/>
      <inertia ixx="0.00015" ixy="0.0000341" ixz="0.0000118" iyy="0.000255" iyz="0.00000229" izz="0.000350"/>
    </inertial>
  </link>
  <joint name="leg_6/J3_elbow/X5_9" type="revolute">
    <parent link="leg_6/J3_elbow/INPUT_INTERFACE"/>
    <child link="leg_6/elbow_end/INPUT_INTERFACE"/>
    <origin rpy="0 0 0" xyz="0 0 0.031"/>
    <axis xyz="0 0 1"/>
    <limit effort="13.0" lower="0.785" upper="2.356" velocity="1.466"/>
    <dynamics damping="0.1" friction="0.1"/>
  </joint>
  <link name="leg_6/elbow_end/INPUT_INTERFACE">
    <!--visual>
        <origin xyz="0 0 0" rpy="0 0 0" />
        <geometry>
          <mesh filename="package://hebi_description/meshes/A-2038-02.stl"/>
        </geometry>
        <xacro:black_material/>
      </visual-->
    <visual>
      <origin rpy="0 1.57075 0" xyz="0.1375 0 0.02"/>
      <geometry>
        <cylinder length="0.2496" radius=".016"/>
      </geometry>
      <material name="silver">
        <color rgba="0.6 0.6 0.6 1"/>
      </material>
    </visual>
    <!--visual>
        <origin xyz="${extension} ${sin(-twist) * edge_to_center} ${edge_to_center * (1 + cos(-twist))}" rpy="${-twist} 0 0"/>
        <geometry>
          <mesh filename="package://hebi_description/meshes/A-2039-02.stl"/>
        </geometry>
        <xacro:black_material/>
      </visual-->
    <!--collision>
        <origin xyz="0 0 0" rpy="0 0 0" />
        <geometry>
          <mesh filename="package://hebi_description/meshes/A-2038-02.stl"/>
        </geometry>
      </collision-->
    <collision>
      <origin rpy="0 1.57075 0" xyz="0.1375 0 0.02"/>
      <geometry>
        <cylinder length="0.2496" radius=".016"/>
      </geometry>
    </collision>
    <!--collision>
        <origin xyz="${extension} ${sin(-twist) * edge_to_center} ${edge_to_center * (1 + cos(-twist))}" rpy="${-twist} 0 0"/>
        <geometry>
          <mesh filename="package://hebi_description/meshes/A-2039-02.stl"/>
        </geometry>
      </collision-->
    <!-- Approximate inertia as thin rod about x axis -->
    <inertial>
      <origin rpy="0 0 0" xyz="0.1375 0 0.02"/>
      <mass value="0.382"/>
      <inertia ixx="0.0" ixy="0.0" ixz="0.0" iyy="0.00240739583333" iyz="0.0" izz="0.00240739583333"/>
    </inertial>
  </link>
  <joint name="leg_6/elbow_end/OUTPUT_JOINT" type="fixed">
    <parent link="leg_6/elbow_end/INPUT_INTERFACE"/>
    <child link="leg_6/foot/INPUT_INTERFACE"/>
    <origin rpy="0 0 0" xyz="0.275 -0.0 0.04"/>
  </joint>
  <link name="leg_6/foot/INPUT_INTERFACE">
    <inertial>
      <origin rpy="0 0 0" xyz="0 0 -.02"/>
      <mass value="0.01"/>
      <inertia ixx="0.0001" ixy="0" ixz="0" iyy="0.0001" iyz="0" izz="0.0001"/>
    </inertial>
    <visual>
      <geometry>
        <sphere radius="0.02"/>
      </geometry>
      <origin rpy="0 0 0" xyz="0 0 -.02"/>
      <material name="black">
        <color rgba="0.1 0.1 0.1 1"/>
      </material>
    </visual>
    <collision>
      <geometry>
        <sphere radius="0.02"/>
      </geometry>
      <origin rpy="0 0 0" xyz="0 0 -.02"/>
    </collision>
  </link>
  <!-- use rubber bit for foot end link; necessary to provide output for HEBI components to attach to. -->
</robot>

