<?xml version="1.0" ?>
<!-- =================================================================================== -->
<!-- |    This document was autogenerated by xacro from /home/cobracommander/modular_mbrl/urdf/wnnnnn.xacro | -->
<!-- |    EDITING THIS FILE BY HAND IS NOT RECOMMENDED                                 | -->
<!-- =================================================================================== -->
<robot name="wnnnnn" xmlns:xacro="http://www.ros.org/wiki/xacro">
  <!-- This is a single xacro file you can include to get
  all of the HEBI components -->
  <!-- <xacro:include filename="end_effector.xacro"/> -->
  <!-- This automatically loads the gazebo plugin for xacro models
       which include hebi.xacro 
  <gazebo>
    <plugin name="hebi_gazebo_plugin" filename="libhebi_gazebo_plugin.so"/>
  </gazebo>-->
  <link name="chassis">
    <visual>
      <geometry>
        <mesh filename="base_plate.stl" scale="0.001 0.001 0.001"/>
      </geometry>
      <origin rpy="1.57079632679 0 1.57079632679" xyz="0 0 0"/>
      <material name="silver">
        <color rgba="0.6 0.6 0.6 1"/>
      </material>
    </visual>
    <collision>
      <geometry>
        <mesh filename="base_plate.stl" scale="0.001 0.001 0.001"/>
      </geometry>
      <origin rpy="1.57079632679 0 1.57079632679" xyz="0 0 0"/>
    </collision>
    <inertial>
      <!--mass value="2.7"/no battery-->
      <mass value="3.4"/>
      <!-- with  1 battery -->
      <inertia ixx="0.02" ixy="0.0" ixz="0.0" iyy="0.02" iyz="0.0" izz="0.05"/>
      <origin rpy="0 0 0" xyz="-0.02 0 0"/>
    </inertial>
    <visual>
      <geometry>
        <box size="0.15 0.02 0.02"/>
      </geometry>
      <origin rpy="0 0 0" xyz="0.075 0 0.0195"/>
      <material name="silver">
        <color rgba="0.6 0.6 0.6 1"/>
      </material>
    </visual>
  </link>
  <geometry>
    <box size="0.15 0.02 0.02"/>
  </geometry>
  <origin rpy="0 0 0" xyz="0.01 0 0.0345"/>
  <!-- connect leg to chassis -->
  <joint name="base_wheel_1" type="fixed">
    <parent link="chassis"/>
    <child link="wheel_1/J1_base/INPUT_INTERFACE"/>
    <origin rpy="3.14159265359 0 -1.0471975512" xyz="0.1524 0.0880 0"/>
  </joint>
  <link name="wheel_1/J1_base/INPUT_INTERFACE">
    <visual>
      <origin rpy="0 0 0" xyz="0 0 0.0125"/>
      <geometry>
        <cylinder length="0.025" radius="0.035"/>
      </geometry>
      <material name="red">
        <color rgba=".82 0.06 0.06 1"/>
      </material>
    </visual>
    <collision>
      <origin rpy="0 0 0" xyz="0 0 0.0125"/>
      <geometry>
        <cylinder length="0.025" radius="0.035"/>
      </geometry>
    </collision>
    <inertial>
      <origin rpy="0 0 0" xyz="-0.0142 -0.0031 0.0165"/>
      <mass value="0.36"/>
      <inertia ixx="0.00015" ixy="0.0000341" ixz="0.0000118" iyy="0.000255" iyz="0.00000229" izz="0.000350"/>
    </inertial>
  </link>
  <joint name="wheel_1/J1_base/X5_9" type="revolute">
    <parent link="wheel_1/J1_base/INPUT_INTERFACE"/>
    <child link="wheel_1/shoulder_bracket/INPUT_INTERFACE"/>
    <origin rpy="0 0 0" xyz="0 0 0.031"/>
    <axis xyz="0 0 1"/>
    <limit effort="13.0" lower="-1.0471975512" upper="1.0471975512" velocity="1.466"/>
    <dynamics damping="0.1" friction="0.1"/>
  </joint>
  <link name="wheel_1/shoulder_bracket/INPUT_INTERFACE">
    <visual>
      <origin rpy="1.57079632679 0 1.57079632679" xyz="0 0 0.005"/>
      <geometry>
        <mesh filename="PM-2149-01.stl" scale="0.001 0.001 0.001"/>
      </geometry>
      <material name="black">
        <color rgba="0.1 0.1 0.1 1"/>
      </material>
    </visual>
    <visual>
      <origin rpy="1.57079632679 0 0" xyz="0 -.03 .04"/>
      <geometry>
        <mesh filename="PM-2150-01R.stl" scale="0.001 0.001 0.001"/>
      </geometry>
      <material name="black">
        <color rgba="0.1 0.1 0.1 1"/>
      </material>
    </visual>
    <!-- REMOVED COLLISION FOR SPEED

      <collision>
        <xacro:if value="${bracket_type.endswith('RightOutside')}">
          <origin xyz="0 0 0.005" rpy="${pi/2} 0 ${pi/2}"/>
        </xacro:if>
        <xacro:if value="${bracket_type.endswith('RightInside')}">
          <origin xyz="0 0 0.005" rpy="${pi/2} 0 ${-pi/2}"/>
        </xacro:if>
        <xacro:if value="${bracket_type.endswith('LeftOutside')}">
          <origin xyz="0 0 0.005" rpy="${pi/2} 0 ${-pi/2}"/>
        </xacro:if>
        <xacro:if value="${bracket_type.endswith('LeftInside')}">
          <origin xyz="0 0 0.005" rpy="${pi/2} 0 ${pi/2}"/>
        </xacro:if>
        <geometry>
          <mesh filename="PM-2149-01.stl" scale="0.001 0.001 0.001"/>
        </geometry>
      </collision>
      <collision>
        <xacro:if value="${bracket_type.endswith('RightOutside')}">
          <origin xyz="0 -.03 .04" rpy="${pi/2} 0 0"/>
        </xacro:if>
        <xacro:if value="${bracket_type.endswith('RightInside')}">
          <origin xyz="0 .03 .04" rpy="${pi/2} 0 0"/>
        </xacro:if>
        <xacro:if value="${bracket_type.endswith('LeftOutside')}">
          <origin xyz="0 .03 .04" rpy="${pi/2} 0 ${pi}"/>
        </xacro:if>
        <xacro:if value="${bracket_type.endswith('LeftInside')}">
          <origin xyz="0 -.03 .04" rpy="${pi/2} 0 ${pi}"/>
        </xacro:if>
        <geometry>
          <xacro:if value="${bracket_type.startswith('X5HeavyRight') or bracket_type.startswith('R5HeavyRight')}">
            <mesh filename="PM-2150-01R.stl" scale="0.001 0.001 0.001"/>
          </xacro:if>
          <xacro:if value="${bracket_type.startswith('X5HeavyLeft') or bracket_type.startswith('R5HeavyLeft')}">
            <mesh filename="PM-2150-01L.stl" scale="0.001 0.001 0.001"/>
          </xacro:if>
        </geometry>
      </collision>
      -->
    <!-- NOTE: inertia is just modelled as small sphere, and could be improved. -->
    <inertial>
      <origin rpy="0 0 0" xyz="0 -0.01875 .0275"/>
      <mass value="0.215"/>
      <inertia ixx="0.0003096" ixy="0.0" ixz="0.0" iyy="0.0003096" iyz="0.0" izz="0.0003096"/>
    </inertial>
  </link>
  <joint name="wheel_1/shoulder_bracket/OUTPUT_INTERFACE" type="fixed">
    <parent link="wheel_1/shoulder_bracket/INPUT_INTERFACE"/>
    <child link="wheel_1/J2_shoulder/INPUT_INTERFACE"/>
    <origin rpy="1.57079632679 0 0" xyz="0 -.0375 .055"/>
  </joint>
  <link name="wheel_1/J2_shoulder/INPUT_INTERFACE">
    <visual>
      <origin rpy="0 0 0" xyz="0 0 0.02"/>
      <geometry>
        <cylinder length="0.04" radius="0.035"/>
      </geometry>
      <material name="red">
        <color rgba=".82 0.06 0.06 1"/>
      </material>
    </visual>
    <collision>
      <origin rpy="0 0 0" xyz="0 0 0.02"/>
      <geometry>
        <cylinder length="0.04" radius="0.035"/>
      </geometry>
    </collision>
    <inertial>
      <origin rpy="0 0 0" xyz="-0.0145 -0.0031 0.0242"/>
      <mass value="0.48"/>
      <inertia ixx="0.000246" ixy="0.0000444" ixz="0.0000266" iyy="0.000380" iyz="0.00000422" izz="0.000463"/>
    </inertial>
  </link>
  <joint name="wheel_1/J2_shoulder/X8_9" type="continuous">
    <parent link="wheel_1/J2_shoulder/INPUT_INTERFACE"/>
    <child link="wheel_1/wheel/INPUT_INTERFACE"/>
    <origin rpy="0 0 0" xyz="0 0 0.045"/>
    <axis xyz="0 0 1"/>
    <limit effort="20" velocity="3.14"/>
    <dynamics damping="0.5" friction="0.5"/>
  </joint>
  <link name="wheel_1/wheel/INPUT_INTERFACE">
    <inertial>
      <origin rpy="0 0 0" xyz="0 0 0"/>
      <mass value="0.498"/>
      <inertia ixx="0.001" ixy="0" ixz="0" iyy="0.001" iyz="0" izz="0.002"/>
    </inertial>
    <visual>
      <geometry>
        <cylinder length="0.0254" radius="0.105"/>
      </geometry>
      <origin rpy="0 0 0" xyz="0 0 0.015"/>
      <material name="black">
        <color rgba="0.1 0.1 0.1 1"/>
      </material>
    </visual>
    <collision>
      <geometry>
        <cylinder length="0.0254" radius="0.105"/>
      </geometry>
      <origin rpy="0 0 0" xyz="0 0 0.015"/>
    </collision>
  </link>
  <!-- No limb at port 2-->
  <!-- No limb at port 3-->
  <!-- No limb at port 4-->
  <!-- No limb at port 5-->
  <!-- No limb at port 6-->
</robot>

