<?xml version="1.0" ?>
<!-- =================================================================================== -->
<!-- |    This document was autogenerated by xacro from /home/cobracommander/modular_mbrl/mbrl/urdf/wwwlnl.xacro | -->
<!-- |    EDITING THIS FILE BY HAND IS NOT RECOMMENDED                                 | -->
<!-- =================================================================================== -->
<robot name="wwwlnl" xmlns:xacro="http://www.ros.org/wiki/xacro">
  <!-- This is a single xacro file you can include to get
  all of the HEBI components -->
  <!-- <xacro:include filename="end_effector.xacro"/> -->
  <!-- This automatically loads the gazebo plugin for xacro models
       which include hebi.xacro -->
  <gazebo>
    <plugin filename="libhebi_gazebo_plugin.so" name="hebi_gazebo_plugin"/>
  </gazebo>
  <link name="chassis">
    <visual>
      <geometry>
        <mesh filename="base_plate.stl" scale="0.001 0.001 0.001"/>
      </geometry>
      <origin rpy="1.5707963267948966 0 1.5707963267948966" xyz="0 0 0"/>
      <material name="silver">
        <color rgba="0.6 0.6 0.6 1"/>
      </material>
    </visual>
    <collision>
      <geometry>
        <mesh filename="base_plate.stl" scale="0.001 0.001 0.001"/>
      </geometry>
      <origin rpy="1.5707963267948966 0 1.5707963267948966" xyz="0 0 0"/>
    </collision>
    <inertial>
      <!--mass value="2.7"/no battery-->
      <mass value="3.4"/>
      <!-- with  1 battery -->
      <inertia ixx="0.02" ixy="0.0" ixz="0.0" iyy="0.02" iyz="0.0" izz="0.05"/>
      <origin rpy="0 0 0" xyz="0 0 0"/>
    </inertial>
    <visual>
      <geometry>
        <box size="0.15 0.02 0.02"/>
      </geometry>
      <origin rpy="0 0 0" xyz="0.075 0 0.0195"/>
      <material name="silver">
        <color rgba="0.6 0.6 0.6 1"/>
      </material>
    </visual>
  </link>
  <geometry>
    <box size="0.15 0.02 0.02"/>
  </geometry>
  <origin rpy="0 0 0" xyz="0.01 0 0.0345"/>
  <!-- connect leg to chassis -->
  <joint name="base_wheel_1" type="fixed">
    <parent link="chassis"/>
    <child link="wheel_1/J1_base/INPUT_INTERFACE"/>
    <origin rpy="3.141592653589793 0 -1.0471975511965979" xyz="0.1524 0.0880 0"/>
  </joint>
  <link name="wheel_1/J1_base/INPUT_INTERFACE">
    <visual>
      <origin rpy="0 0 0" xyz="0 0 0"/>
      <geometry>
        <mesh filename="X5.stl" scale="0.001 0.001 0.001"/>
      </geometry>
      <material name="red">
        <color rgba=".82 0.06 0.06 1"/>
      </material>
    </visual>
    <collision>
      <origin rpy="0 0 0" xyz="0 0 0"/>
      <geometry>
        <mesh filename="X5.stl" scale="0.001 0.001 0.001"/>
      </geometry>
    </collision>
    <inertial>
      <origin rpy="0 0 0" xyz="-0.0142 -0.0031 0.0165"/>
      <mass value="0.36"/>
      <inertia ixx="0.00015" ixy="0.0000341" ixz="0.0000118" iyy="0.000255" iyz="0.00000229" izz="0.000350"/>
    </inertial>
  </link>
  <gazebo reference="wheel_1/J1_base/INPUT_INTERFACE">
    <material>Gazebo/Red</material>
  </gazebo>
  <joint name="wheel_1/J1_base/X5_9" type="revolute">
    <parent link="wheel_1/J1_base/INPUT_INTERFACE"/>
    <child link="wheel_1/shoulder_bracket/INPUT_INTERFACE"/>
    <origin rpy="0 0 0" xyz="0 0 0.031"/>
    <axis xyz="0 0 1"/>
    <limit effort="13.0" lower="-0.7853981633974483" upper="0.7853981633974483" velocity="14"/>
    <dynamics damping="0.1" friction="0.1"/>
  </joint>
  <link name="wheel_1/shoulder_bracket/INPUT_INTERFACE">
    <!-- REMOVED VISUAL AND COLLISION FOR SPEED
      <visual>
        <xacro:if value="${bracket_type.endswith('RightOutside')}">
          <origin xyz="0 0 0.005" rpy="${pi/2} 0 ${pi/2}"/>
        </xacro:if>
        <xacro:if value="${bracket_type.endswith('RightInside')}">
          <origin xyz="0 0 0.005" rpy="${pi/2} 0 ${-pi/2}"/>
        </xacro:if>
        <xacro:if value="${bracket_type.endswith('LeftOutside')}">
          <origin xyz="0 0 0.005" rpy="${pi/2} 0 ${-pi/2}"/>
        </xacro:if>
        <xacro:if value="${bracket_type.endswith('LeftInside')}">
          <origin xyz="0 0 0.005" rpy="${pi/2} 0 ${pi/2}"/>
        </xacro:if>
        <geometry>
          <mesh filename="PM-2149-01.stl" scale="0.001 0.001 0.001"/>
        </geometry>
        <xacro:black_material/>
      </visual>
      <visual>
        <xacro:if value="${bracket_type.endswith('RightOutside')}">
          <origin xyz="0 -.03 .04" rpy="${pi/2} 0 0"/>
        </xacro:if>
        <xacro:if value="${bracket_type.endswith('RightInside')}">
          <origin xyz="0 .03 .04" rpy="${pi/2} 0 0"/>
        </xacro:if>
        <xacro:if value="${bracket_type.endswith('LeftOutside')}">
          <origin xyz="0 -.03 .04" rpy="${pi/2} 0 0"/>
        </xacro:if>
        <xacro:if value="${bracket_type.endswith('LeftInside')}">
          <origin xyz="0 -.03 .04" rpy="${pi/2} 0 ${pi}"/>
        </xacro:if>
        <geometry>
          <xacro:if value="${bracket_type.startswith('X5HeavyRight') or bracket_type.startswith('R5HeavyRight')}">
            <mesh filename="PM-2150-01R.stl" scale="0.001 0.001 0.001"/>
          </xacro:if>
          <xacro:if value="${bracket_type.startswith('X5HeavyLeft') or bracket_type.startswith('R5HeavyLeft')}">
            <mesh filename="PM-2150-01L.stl" scale="0.001 0.001 0.001"/>
          </xacro:if>
        </geometry>
        <xacro:black_material/>
      </visual>

      <collision>
        <xacro:if value="${bracket_type.endswith('RightOutside')}">
          <origin xyz="0 0 0.005" rpy="${pi/2} 0 ${pi/2}"/>
        </xacro:if>
        <xacro:if value="${bracket_type.endswith('RightInside')}">
          <origin xyz="0 0 0.005" rpy="${pi/2} 0 ${-pi/2}"/>
        </xacro:if>
        <xacro:if value="${bracket_type.endswith('LeftOutside')}">
          <origin xyz="0 0 0.005" rpy="${pi/2} 0 ${-pi/2}"/>
        </xacro:if>
        <xacro:if value="${bracket_type.endswith('LeftInside')}">
          <origin xyz="0 0 0.005" rpy="${pi/2} 0 ${pi/2}"/>
        </xacro:if>
        <geometry>
          <mesh filename="PM-2149-01.stl" scale="0.001 0.001 0.001"/>
        </geometry>
      </collision>
      <collision>
        <xacro:if value="${bracket_type.endswith('RightOutside')}">
          <origin xyz="0 -.03 .04" rpy="${pi/2} 0 0"/>
        </xacro:if>
        <xacro:if value="${bracket_type.endswith('RightInside')}">
          <origin xyz="0 .03 .04" rpy="${pi/2} 0 0"/>
        </xacro:if>
        <xacro:if value="${bracket_type.endswith('LeftOutside')}">
          <origin xyz="0 .03 .04" rpy="${pi/2} 0 ${pi}"/>
        </xacro:if>
        <xacro:if value="${bracket_type.endswith('LeftInside')}">
          <origin xyz="0 -.03 .04" rpy="${pi/2} 0 ${pi}"/>
        </xacro:if>
        <geometry>
          <xacro:if value="${bracket_type.startswith('X5HeavyRight') or bracket_type.startswith('R5HeavyRight')}">
            <mesh filename="PM-2150-01R.stl" scale="0.001 0.001 0.001"/>
          </xacro:if>
          <xacro:if value="${bracket_type.startswith('X5HeavyLeft') or bracket_type.startswith('R5HeavyLeft')}">
            <mesh filename="PM-2150-01L.stl" scale="0.001 0.001 0.001"/>
          </xacro:if>
        </geometry>
      </collision>
      -->
    <!-- NOTE: inertia is just modelled as small sphere, and could be improved. -->
    <inertial>
      <origin rpy="0 0 0" xyz="0 -0.01875 .0275"/>
      <mass value="0.215"/>
      <inertia ixx="0.00030960000000000004" ixy="0.0" ixz="0.0" iyy="0.00030960000000000004" iyz="0.0" izz="0.00030960000000000004"/>
    </inertial>
  </link>
  <gazebo reference="wheel_1/shoulder_bracket/INPUT_INTERFACE">
    <material>Gazebo/Black</material>
  </gazebo>
  <joint name="wheel_1/shoulder_bracket/OUTPUT_INTERFACE" type="fixed">
    <parent link="wheel_1/shoulder_bracket/INPUT_INTERFACE"/>
    <child link="wheel_1/J2_shoulder/INPUT_INTERFACE"/>
    <origin rpy="1.5707963267948966 0 0" xyz="0 -.0375 .055"/>
  </joint>
  <gazebo reference="wheel_1/shoulder_bracket/OUTPUT_INTERFACE">
    <disableFixedJointLumping>true</disableFixedJointLumping>
    <preserveFixedJoint>true</preserveFixedJoint>
  </gazebo>
  <link name="wheel_1/J2_shoulder/INPUT_INTERFACE">
    <visual>
      <origin rpy="0 0 0" xyz="0 0 0"/>
      <geometry>
        <mesh filename="X8.stl" scale="0.001 0.001 0.001"/>
      </geometry>
      <material name="red">
        <color rgba=".82 0.06 0.06 1"/>
      </material>
    </visual>
    <collision>
      <origin rpy="0 0 0" xyz="0 0 0"/>
      <geometry>
        <mesh filename="X8.stl" scale="0.001 0.001 0.001"/>
      </geometry>
    </collision>
    <inertial>
      <origin rpy="0 0 0" xyz="-0.0145 -0.0031 0.0242"/>
      <mass value="0.48"/>
      <inertia ixx="0.000246" ixy="0.0000444" ixz="0.0000266" iyy="0.000380" iyz="0.00000422" izz="0.000463"/>
    </inertial>
  </link>
  <gazebo reference="wheel_1/J2_shoulder/INPUT_INTERFACE">
    <material>Gazebo/Red</material>
  </gazebo>
  <joint name="wheel_1/J2_shoulder/X8_9" type="continuous">
    <parent link="wheel_1/J2_shoulder/INPUT_INTERFACE"/>
    <child link="wheel_1/wheel/INPUT_INTERFACE"/>
    <origin rpy="0 0 0" xyz="0 0 0.045"/>
    <axis xyz="0 0 1"/>
    <limit effort="20" velocity="30"/>
    <dynamics damping="0.5" friction="0.5"/>
  </joint>
  <link name="wheel_1/wheel/INPUT_INTERFACE">
    <inertial>
      <origin rpy="0 0 0" xyz="0 0 0"/>
      <mass value="0.498"/>
      <inertia ixx="0.001" ixy="0" ixz="0" iyy="0.001" iyz="0" izz="0.002"/>
    </inertial>
    <visual>
      <geometry>
        <cylinder length="0.0254" radius="0.105"/>
      </geometry>
      <origin rpy="0 0 0" xyz="0 0 0.015"/>
      <material name="black">
        <color rgba="0.1 0.1 0.1 1"/>
      </material>
    </visual>
    <collision>
      <geometry>
        <cylinder length="0.0254" radius="0.1016"/>
      </geometry>
      <origin rpy="0 0 0" xyz="0 0 0.015"/>
    </collision>
  </link>
  <!-- connect leg to chassis -->
  <joint name="base_wheel_2" type="fixed">
    <parent link="chassis"/>
    <child link="wheel_2/J1_base/INPUT_INTERFACE"/>
    <origin rpy="3.141592653589793 0 0.0" xyz="0 0.1760    0"/>
  </joint>
  <link name="wheel_2/J1_base/INPUT_INTERFACE">
    <visual>
      <origin rpy="0 0 0" xyz="0 0 0"/>
      <geometry>
        <mesh filename="X5.stl" scale="0.001 0.001 0.001"/>
      </geometry>
      <material name="red">
        <color rgba=".82 0.06 0.06 1"/>
      </material>
    </visual>
    <collision>
      <origin rpy="0 0 0" xyz="0 0 0"/>
      <geometry>
        <mesh filename="X5.stl" scale="0.001 0.001 0.001"/>
      </geometry>
    </collision>
    <inertial>
      <origin rpy="0 0 0" xyz="-0.0142 -0.0031 0.0165"/>
      <mass value="0.36"/>
      <inertia ixx="0.00015" ixy="0.0000341" ixz="0.0000118" iyy="0.000255" iyz="0.00000229" izz="0.000350"/>
    </inertial>
  </link>
  <gazebo reference="wheel_2/J1_base/INPUT_INTERFACE">
    <material>Gazebo/Red</material>
  </gazebo>
  <joint name="wheel_2/J1_base/X5_9" type="revolute">
    <parent link="wheel_2/J1_base/INPUT_INTERFACE"/>
    <child link="wheel_2/shoulder_bracket/INPUT_INTERFACE"/>
    <origin rpy="0 0 0" xyz="0 0 0.031"/>
    <axis xyz="0 0 1"/>
    <limit effort="13.0" lower="-0.7853981633974483" upper="0.7853981633974483" velocity="14"/>
    <dynamics damping="0.1" friction="0.1"/>
  </joint>
  <link name="wheel_2/shoulder_bracket/INPUT_INTERFACE">
    <!-- REMOVED VISUAL AND COLLISION FOR SPEED
      <visual>
        <xacro:if value="${bracket_type.endswith('RightOutside')}">
          <origin xyz="0 0 0.005" rpy="${pi/2} 0 ${pi/2}"/>
        </xacro:if>
        <xacro:if value="${bracket_type.endswith('RightInside')}">
          <origin xyz="0 0 0.005" rpy="${pi/2} 0 ${-pi/2}"/>
        </xacro:if>
        <xacro:if value="${bracket_type.endswith('LeftOutside')}">
          <origin xyz="0 0 0.005" rpy="${pi/2} 0 ${-pi/2}"/>
        </xacro:if>
        <xacro:if value="${bracket_type.endswith('LeftInside')}">
          <origin xyz="0 0 0.005" rpy="${pi/2} 0 ${pi/2}"/>
        </xacro:if>
        <geometry>
          <mesh filename="PM-2149-01.stl" scale="0.001 0.001 0.001"/>
        </geometry>
        <xacro:black_material/>
      </visual>
      <visual>
        <xacro:if value="${bracket_type.endswith('RightOutside')}">
          <origin xyz="0 -.03 .04" rpy="${pi/2} 0 0"/>
        </xacro:if>
        <xacro:if value="${bracket_type.endswith('RightInside')}">
          <origin xyz="0 .03 .04" rpy="${pi/2} 0 0"/>
        </xacro:if>
        <xacro:if value="${bracket_type.endswith('LeftOutside')}">
          <origin xyz="0 -.03 .04" rpy="${pi/2} 0 0"/>
        </xacro:if>
        <xacro:if value="${bracket_type.endswith('LeftInside')}">
          <origin xyz="0 -.03 .04" rpy="${pi/2} 0 ${pi}"/>
        </xacro:if>
        <geometry>
          <xacro:if value="${bracket_type.startswith('X5HeavyRight') or bracket_type.startswith('R5HeavyRight')}">
            <mesh filename="PM-2150-01R.stl" scale="0.001 0.001 0.001"/>
          </xacro:if>
          <xacro:if value="${bracket_type.startswith('X5HeavyLeft') or bracket_type.startswith('R5HeavyLeft')}">
            <mesh filename="PM-2150-01L.stl" scale="0.001 0.001 0.001"/>
          </xacro:if>
        </geometry>
        <xacro:black_material/>
      </visual>

      <collision>
        <xacro:if value="${bracket_type.endswith('RightOutside')}">
          <origin xyz="0 0 0.005" rpy="${pi/2} 0 ${pi/2}"/>
        </xacro:if>
        <xacro:if value="${bracket_type.endswith('RightInside')}">
          <origin xyz="0 0 0.005" rpy="${pi/2} 0 ${-pi/2}"/>
        </xacro:if>
        <xacro:if value="${bracket_type.endswith('LeftOutside')}">
          <origin xyz="0 0 0.005" rpy="${pi/2} 0 ${-pi/2}"/>
        </xacro:if>
        <xacro:if value="${bracket_type.endswith('LeftInside')}">
          <origin xyz="0 0 0.005" rpy="${pi/2} 0 ${pi/2}"/>
        </xacro:if>
        <geometry>
          <mesh filename="PM-2149-01.stl" scale="0.001 0.001 0.001"/>
        </geometry>
      </collision>
      <collision>
        <xacro:if value="${bracket_type.endswith('RightOutside')}">
          <origin xyz="0 -.03 .04" rpy="${pi/2} 0 0"/>
        </xacro:if>
        <xacro:if value="${bracket_type.endswith('RightInside')}">
          <origin xyz="0 .03 .04" rpy="${pi/2} 0 0"/>
        </xacro:if>
        <xacro:if value="${bracket_type.endswith('LeftOutside')}">
          <origin xyz="0 .03 .04" rpy="${pi/2} 0 ${pi}"/>
        </xacro:if>
        <xacro:if value="${bracket_type.endswith('LeftInside')}">
          <origin xyz="0 -.03 .04" rpy="${pi/2} 0 ${pi}"/>
        </xacro:if>
        <geometry>
          <xacro:if value="${bracket_type.startswith('X5HeavyRight') or bracket_type.startswith('R5HeavyRight')}">
            <mesh filename="PM-2150-01R.stl" scale="0.001 0.001 0.001"/>
          </xacro:if>
          <xacro:if value="${bracket_type.startswith('X5HeavyLeft') or bracket_type.startswith('R5HeavyLeft')}">
            <mesh filename="PM-2150-01L.stl" scale="0.001 0.001 0.001"/>
          </xacro:if>
        </geometry>
      </collision>
      -->
    <!-- NOTE: inertia is just modelled as small sphere, and could be improved. -->
    <inertial>
      <origin rpy="0 0 0" xyz="0 -0.01875 .0275"/>
      <mass value="0.215"/>
      <inertia ixx="0.00030960000000000004" ixy="0.0" ixz="0.0" iyy="0.00030960000000000004" iyz="0.0" izz="0.00030960000000000004"/>
    </inertial>
  </link>
  <gazebo reference="wheel_2/shoulder_bracket/INPUT_INTERFACE">
    <material>Gazebo/Black</material>
  </gazebo>
  <joint name="wheel_2/shoulder_bracket/OUTPUT_INTERFACE" type="fixed">
    <parent link="wheel_2/shoulder_bracket/INPUT_INTERFACE"/>
    <child link="wheel_2/J2_shoulder/INPUT_INTERFACE"/>
    <origin rpy="1.5707963267948966 0 0" xyz="0 -.0375 .055"/>
  </joint>
  <gazebo reference="wheel_2/shoulder_bracket/OUTPUT_INTERFACE">
    <disableFixedJointLumping>true</disableFixedJointLumping>
    <preserveFixedJoint>true</preserveFixedJoint>
  </gazebo>
  <link name="wheel_2/J2_shoulder/INPUT_INTERFACE">
    <visual>
      <origin rpy="0 0 0" xyz="0 0 0"/>
      <geometry>
        <mesh filename="X8.stl" scale="0.001 0.001 0.001"/>
      </geometry>
      <material name="red">
        <color rgba=".82 0.06 0.06 1"/>
      </material>
    </visual>
    <collision>
      <origin rpy="0 0 0" xyz="0 0 0"/>
      <geometry>
        <mesh filename="X8.stl" scale="0.001 0.001 0.001"/>
      </geometry>
    </collision>
    <inertial>
      <origin rpy="0 0 0" xyz="-0.0145 -0.0031 0.0242"/>
      <mass value="0.48"/>
      <inertia ixx="0.000246" ixy="0.0000444" ixz="0.0000266" iyy="0.000380" iyz="0.00000422" izz="0.000463"/>
    </inertial>
  </link>
  <gazebo reference="wheel_2/J2_shoulder/INPUT_INTERFACE">
    <material>Gazebo/Red</material>
  </gazebo>
  <joint name="wheel_2/J2_shoulder/X8_9" type="continuous">
    <parent link="wheel_2/J2_shoulder/INPUT_INTERFACE"/>
    <child link="wheel_2/wheel/INPUT_INTERFACE"/>
    <origin rpy="0 0 0" xyz="0 0 0.045"/>
    <axis xyz="0 0 1"/>
    <limit effort="20" velocity="30"/>
    <dynamics damping="0.5" friction="0.5"/>
  </joint>
  <link name="wheel_2/wheel/INPUT_INTERFACE">
    <inertial>
      <origin rpy="0 0 0" xyz="0 0 0"/>
      <mass value="0.498"/>
      <inertia ixx="0.001" ixy="0" ixz="0" iyy="0.001" iyz="0" izz="0.002"/>
    </inertial>
    <visual>
      <geometry>
        <cylinder length="0.0254" radius="0.105"/>
      </geometry>
      <origin rpy="0 0 0" xyz="0 0 0.015"/>
      <material name="black">
        <color rgba="0.1 0.1 0.1 1"/>
      </material>
    </visual>
    <collision>
      <geometry>
        <cylinder length="0.0254" radius="0.1016"/>
      </geometry>
      <origin rpy="0 0 0" xyz="0 0 0.015"/>
    </collision>
  </link>
  <!-- connect leg to chassis -->
  <joint name="base_wheel_3" type="fixed">
    <parent link="chassis"/>
    <child link="wheel_3/J1_base/INPUT_INTERFACE"/>
    <origin rpy="3.141592653589793 0 1.0471975511965979" xyz="-0.1524 0.0880 0"/>
  </joint>
  <link name="wheel_3/J1_base/INPUT_INTERFACE">
    <visual>
      <origin rpy="0 0 0" xyz="0 0 0"/>
      <geometry>
        <mesh filename="X5.stl" scale="0.001 0.001 0.001"/>
      </geometry>
      <material name="red">
        <color rgba=".82 0.06 0.06 1"/>
      </material>
    </visual>
    <collision>
      <origin rpy="0 0 0" xyz="0 0 0"/>
      <geometry>
        <mesh filename="X5.stl" scale="0.001 0.001 0.001"/>
      </geometry>
    </collision>
    <inertial>
      <origin rpy="0 0 0" xyz="-0.0142 -0.0031 0.0165"/>
      <mass value="0.36"/>
      <inertia ixx="0.00015" ixy="0.0000341" ixz="0.0000118" iyy="0.000255" iyz="0.00000229" izz="0.000350"/>
    </inertial>
  </link>
  <gazebo reference="wheel_3/J1_base/INPUT_INTERFACE">
    <material>Gazebo/Red</material>
  </gazebo>
  <joint name="wheel_3/J1_base/X5_9" type="revolute">
    <parent link="wheel_3/J1_base/INPUT_INTERFACE"/>
    <child link="wheel_3/shoulder_bracket/INPUT_INTERFACE"/>
    <origin rpy="0 0 0" xyz="0 0 0.031"/>
    <axis xyz="0 0 1"/>
    <limit effort="13.0" lower="-0.7853981633974483" upper="0.7853981633974483" velocity="14"/>
    <dynamics damping="0.1" friction="0.1"/>
  </joint>
  <link name="wheel_3/shoulder_bracket/INPUT_INTERFACE">
    <!-- REMOVED VISUAL AND COLLISION FOR SPEED
      <visual>
        <xacro:if value="${bracket_type.endswith('RightOutside')}">
          <origin xyz="0 0 0.005" rpy="${pi/2} 0 ${pi/2}"/>
        </xacro:if>
        <xacro:if value="${bracket_type.endswith('RightInside')}">
          <origin xyz="0 0 0.005" rpy="${pi/2} 0 ${-pi/2}"/>
        </xacro:if>
        <xacro:if value="${bracket_type.endswith('LeftOutside')}">
          <origin xyz="0 0 0.005" rpy="${pi/2} 0 ${-pi/2}"/>
        </xacro:if>
        <xacro:if value="${bracket_type.endswith('LeftInside')}">
          <origin xyz="0 0 0.005" rpy="${pi/2} 0 ${pi/2}"/>
        </xacro:if>
        <geometry>
          <mesh filename="PM-2149-01.stl" scale="0.001 0.001 0.001"/>
        </geometry>
        <xacro:black_material/>
      </visual>
      <visual>
        <xacro:if value="${bracket_type.endswith('RightOutside')}">
          <origin xyz="0 -.03 .04" rpy="${pi/2} 0 0"/>
        </xacro:if>
        <xacro:if value="${bracket_type.endswith('RightInside')}">
          <origin xyz="0 .03 .04" rpy="${pi/2} 0 0"/>
        </xacro:if>
        <xacro:if value="${bracket_type.endswith('LeftOutside')}">
          <origin xyz="0 -.03 .04" rpy="${pi/2} 0 0"/>
        </xacro:if>
        <xacro:if value="${bracket_type.endswith('LeftInside')}">
          <origin xyz="0 -.03 .04" rpy="${pi/2} 0 ${pi}"/>
        </xacro:if>
        <geometry>
          <xacro:if value="${bracket_type.startswith('X5HeavyRight') or bracket_type.startswith('R5HeavyRight')}">
            <mesh filename="PM-2150-01R.stl" scale="0.001 0.001 0.001"/>
          </xacro:if>
          <xacro:if value="${bracket_type.startswith('X5HeavyLeft') or bracket_type.startswith('R5HeavyLeft')}">
            <mesh filename="PM-2150-01L.stl" scale="0.001 0.001 0.001"/>
          </xacro:if>
        </geometry>
        <xacro:black_material/>
      </visual>

      <collision>
        <xacro:if value="${bracket_type.endswith('RightOutside')}">
          <origin xyz="0 0 0.005" rpy="${pi/2} 0 ${pi/2}"/>
        </xacro:if>
        <xacro:if value="${bracket_type.endswith('RightInside')}">
          <origin xyz="0 0 0.005" rpy="${pi/2} 0 ${-pi/2}"/>
        </xacro:if>
        <xacro:if value="${bracket_type.endswith('LeftOutside')}">
          <origin xyz="0 0 0.005" rpy="${pi/2} 0 ${-pi/2}"/>
        </xacro:if>
        <xacro:if value="${bracket_type.endswith('LeftInside')}">
          <origin xyz="0 0 0.005" rpy="${pi/2} 0 ${pi/2}"/>
        </xacro:if>
        <geometry>
          <mesh filename="PM-2149-01.stl" scale="0.001 0.001 0.001"/>
        </geometry>
      </collision>
      <collision>
        <xacro:if value="${bracket_type.endswith('RightOutside')}">
          <origin xyz="0 -.03 .04" rpy="${pi/2} 0 0"/>
        </xacro:if>
        <xacro:if value="${bracket_type.endswith('RightInside')}">
          <origin xyz="0 .03 .04" rpy="${pi/2} 0 0"/>
        </xacro:if>
        <xacro:if value="${bracket_type.endswith('LeftOutside')}">
          <origin xyz="0 .03 .04" rpy="${pi/2} 0 ${pi}"/>
        </xacro:if>
        <xacro:if value="${bracket_type.endswith('LeftInside')}">
          <origin xyz="0 -.03 .04" rpy="${pi/2} 0 ${pi}"/>
        </xacro:if>
        <geometry>
          <xacro:if value="${bracket_type.startswith('X5HeavyRight') or bracket_type.startswith('R5HeavyRight')}">
            <mesh filename="PM-2150-01R.stl" scale="0.001 0.001 0.001"/>
          </xacro:if>
          <xacro:if value="${bracket_type.startswith('X5HeavyLeft') or bracket_type.startswith('R5HeavyLeft')}">
            <mesh filename="PM-2150-01L.stl" scale="0.001 0.001 0.001"/>
          </xacro:if>
        </geometry>
      </collision>
      -->
    <!-- NOTE: inertia is just modelled as small sphere, and could be improved. -->
    <inertial>
      <origin rpy="0 0 0" xyz="0 -0.01875 .0275"/>
      <mass value="0.215"/>
      <inertia ixx="0.00030960000000000004" ixy="0.0" ixz="0.0" iyy="0.00030960000000000004" iyz="0.0" izz="0.00030960000000000004"/>
    </inertial>
  </link>
  <gazebo reference="wheel_3/shoulder_bracket/INPUT_INTERFACE">
    <material>Gazebo/Black</material>
  </gazebo>
  <joint name="wheel_3/shoulder_bracket/OUTPUT_INTERFACE" type="fixed">
    <parent link="wheel_3/shoulder_bracket/INPUT_INTERFACE"/>
    <child link="wheel_3/J2_shoulder/INPUT_INTERFACE"/>
    <origin rpy="1.5707963267948966 0 0" xyz="0 -.0375 .055"/>
  </joint>
  <gazebo reference="wheel_3/shoulder_bracket/OUTPUT_INTERFACE">
    <disableFixedJointLumping>true</disableFixedJointLumping>
    <preserveFixedJoint>true</preserveFixedJoint>
  </gazebo>
  <link name="wheel_3/J2_shoulder/INPUT_INTERFACE">
    <visual>
      <origin rpy="0 0 0" xyz="0 0 0"/>
      <geometry>
        <mesh filename="X8.stl" scale="0.001 0.001 0.001"/>
      </geometry>
      <material name="red">
        <color rgba=".82 0.06 0.06 1"/>
      </material>
    </visual>
    <collision>
      <origin rpy="0 0 0" xyz="0 0 0"/>
      <geometry>
        <mesh filename="X8.stl" scale="0.001 0.001 0.001"/>
      </geometry>
    </collision>
    <inertial>
      <origin rpy="0 0 0" xyz="-0.0145 -0.0031 0.0242"/>
      <mass value="0.48"/>
      <inertia ixx="0.000246" ixy="0.0000444" ixz="0.0000266" iyy="0.000380" iyz="0.00000422" izz="0.000463"/>
    </inertial>
  </link>
  <gazebo reference="wheel_3/J2_shoulder/INPUT_INTERFACE">
    <material>Gazebo/Red</material>
  </gazebo>
  <joint name="wheel_3/J2_shoulder/X8_9" type="continuous">
    <parent link="wheel_3/J2_shoulder/INPUT_INTERFACE"/>
    <child link="wheel_3/wheel/INPUT_INTERFACE"/>
    <origin rpy="0 0 0" xyz="0 0 0.045"/>
    <axis xyz="0 0 1"/>
    <limit effort="20" velocity="30"/>
    <dynamics damping="0.5" friction="0.5"/>
  </joint>
  <link name="wheel_3/wheel/INPUT_INTERFACE">
    <inertial>
      <origin rpy="0 0 0" xyz="0 0 0"/>
      <mass value="0.498"/>
      <inertia ixx="0.001" ixy="0" ixz="0" iyy="0.001" iyz="0" izz="0.002"/>
    </inertial>
    <visual>
      <geometry>
        <cylinder length="0.0254" radius="0.105"/>
      </geometry>
      <origin rpy="0 0 0" xyz="0 0 0.015"/>
      <material name="black">
        <color rgba="0.1 0.1 0.1 1"/>
      </material>
    </visual>
    <collision>
      <geometry>
        <cylinder length="0.0254" radius="0.1016"/>
      </geometry>
      <origin rpy="0 0 0" xyz="0 0 0.015"/>
    </collision>
  </link>
  <!-- connect leg to chassis -->
  <joint name="base_leg_4" type="fixed">
    <parent link="chassis"/>
    <child link="leg_4/J1_base/INPUT_INTERFACE"/>
    <origin rpy="0 0 2.0943951023931953" xyz="-0.1524 -0.0880  0.0095"/>
  </joint>
  <link name="leg_4/J1_base/INPUT_INTERFACE">
    <visual>
      <origin rpy="0 0 0" xyz="0 0 0"/>
      <geometry>
        <mesh filename="X8.stl" scale="0.001 0.001 0.001"/>
      </geometry>
      <material name="red">
        <color rgba=".82 0.06 0.06 1"/>
      </material>
    </visual>
    <collision>
      <origin rpy="0 0 0" xyz="0 0 0"/>
      <geometry>
        <mesh filename="X8.stl" scale="0.001 0.001 0.001"/>
      </geometry>
    </collision>
    <inertial>
      <origin rpy="0 0 0" xyz="-0.0145 -0.0031 0.0242"/>
      <mass value="0.48"/>
      <inertia ixx="0.000246" ixy="0.0000444" ixz="0.0000266" iyy="0.000380" iyz="0.00000422" izz="0.000463"/>
    </inertial>
  </link>
  <gazebo reference="leg_4/J1_base/INPUT_INTERFACE">
    <material>Gazebo/Red</material>
  </gazebo>
  <joint name="leg_4/J1_base/X8_9" type="revolute">
    <parent link="leg_4/J1_base/INPUT_INTERFACE"/>
    <child link="leg_4/shoulder_bracket/INPUT_INTERFACE"/>
    <origin rpy="0 0 0" xyz="0 0 0.045"/>
    <axis xyz="0 0 1"/>
    <limit effort="20" lower="0.5235987755982988" upper="2.6179938779914944" velocity="30"/>
    <dynamics damping="0.5" friction="0.5"/>
  </joint>
  <link name="leg_4/shoulder_bracket/INPUT_INTERFACE">
    <!-- REMOVED VISUAL AND COLLISION FOR SPEED
      <visual>
        <xacro:if value="${bracket_type.endswith('RightOutside')}">
          <origin xyz="0 0 0.005" rpy="${pi/2} 0 ${pi/2}"/>
        </xacro:if>
        <xacro:if value="${bracket_type.endswith('RightInside')}">
          <origin xyz="0 0 0.005" rpy="${pi/2} 0 ${-pi/2}"/>
        </xacro:if>
        <xacro:if value="${bracket_type.endswith('LeftOutside')}">
          <origin xyz="0 0 0.005" rpy="${pi/2} 0 ${-pi/2}"/>
        </xacro:if>
        <xacro:if value="${bracket_type.endswith('LeftInside')}">
          <origin xyz="0 0 0.005" rpy="${pi/2} 0 ${pi/2}"/>
        </xacro:if>
        <geometry>
          <mesh filename="PM-2149-01.stl" scale="0.001 0.001 0.001"/>
        </geometry>
        <xacro:black_material/>
      </visual>
      <visual>
        <xacro:if value="${bracket_type.endswith('RightOutside')}">
          <origin xyz="0 -.03 .04" rpy="${pi/2} 0 0"/>
        </xacro:if>
        <xacro:if value="${bracket_type.endswith('RightInside')}">
          <origin xyz="0 .03 .04" rpy="${pi/2} 0 0"/>
        </xacro:if>
        <xacro:if value="${bracket_type.endswith('LeftOutside')}">
          <origin xyz="0 -.03 .04" rpy="${pi/2} 0 0"/>
        </xacro:if>
        <xacro:if value="${bracket_type.endswith('LeftInside')}">
          <origin xyz="0 -.03 .04" rpy="${pi/2} 0 ${pi}"/>
        </xacro:if>
        <geometry>
          <xacro:if value="${bracket_type.startswith('X5HeavyRight') or bracket_type.startswith('R5HeavyRight')}">
            <mesh filename="PM-2150-01R.stl" scale="0.001 0.001 0.001"/>
          </xacro:if>
          <xacro:if value="${bracket_type.startswith('X5HeavyLeft') or bracket_type.startswith('R5HeavyLeft')}">
            <mesh filename="PM-2150-01L.stl" scale="0.001 0.001 0.001"/>
          </xacro:if>
        </geometry>
        <xacro:black_material/>
      </visual>

      <collision>
        <xacro:if value="${bracket_type.endswith('RightOutside')}">
          <origin xyz="0 0 0.005" rpy="${pi/2} 0 ${pi/2}"/>
        </xacro:if>
        <xacro:if value="${bracket_type.endswith('RightInside')}">
          <origin xyz="0 0 0.005" rpy="${pi/2} 0 ${-pi/2}"/>
        </xacro:if>
        <xacro:if value="${bracket_type.endswith('LeftOutside')}">
          <origin xyz="0 0 0.005" rpy="${pi/2} 0 ${-pi/2}"/>
        </xacro:if>
        <xacro:if value="${bracket_type.endswith('LeftInside')}">
          <origin xyz="0 0 0.005" rpy="${pi/2} 0 ${pi/2}"/>
        </xacro:if>
        <geometry>
          <mesh filename="PM-2149-01.stl" scale="0.001 0.001 0.001"/>
        </geometry>
      </collision>
      <collision>
        <xacro:if value="${bracket_type.endswith('RightOutside')}">
          <origin xyz="0 -.03 .04" rpy="${pi/2} 0 0"/>
        </xacro:if>
        <xacro:if value="${bracket_type.endswith('RightInside')}">
          <origin xyz="0 .03 .04" rpy="${pi/2} 0 0"/>
        </xacro:if>
        <xacro:if value="${bracket_type.endswith('LeftOutside')}">
          <origin xyz="0 .03 .04" rpy="${pi/2} 0 ${pi}"/>
        </xacro:if>
        <xacro:if value="${bracket_type.endswith('LeftInside')}">
          <origin xyz="0 -.03 .04" rpy="${pi/2} 0 ${pi}"/>
        </xacro:if>
        <geometry>
          <xacro:if value="${bracket_type.startswith('X5HeavyRight') or bracket_type.startswith('R5HeavyRight')}">
            <mesh filename="PM-2150-01R.stl" scale="0.001 0.001 0.001"/>
          </xacro:if>
          <xacro:if value="${bracket_type.startswith('X5HeavyLeft') or bracket_type.startswith('R5HeavyLeft')}">
            <mesh filename="PM-2150-01L.stl" scale="0.001 0.001 0.001"/>
          </xacro:if>
        </geometry>
      </collision>
      -->
    <!-- NOTE: inertia is just modelled as small sphere, and could be improved. -->
    <inertial>
      <origin rpy="0 0 0" xyz="0 0.01125 .0275"/>
      <mass value="0.215"/>
      <inertia ixx="0.00030960000000000004" ixy="0.0" ixz="0.0" iyy="0.00030960000000000004" iyz="0.0" izz="0.00030960000000000004"/>
    </inertial>
  </link>
  <gazebo reference="leg_4/shoulder_bracket/INPUT_INTERFACE">
    <material>Gazebo/Black</material>
  </gazebo>
  <joint name="leg_4/shoulder_bracket/OUTPUT_INTERFACE" type="fixed">
    <parent link="leg_4/shoulder_bracket/INPUT_INTERFACE"/>
    <child link="leg_4/J2_shoulder/INPUT_INTERFACE"/>
    <origin rpy="1.5707963267948966 0 0" xyz="0 .0225 .055"/>
  </joint>
  <gazebo reference="leg_4/shoulder_bracket/OUTPUT_INTERFACE">
    <disableFixedJointLumping>true</disableFixedJointLumping>
    <preserveFixedJoint>true</preserveFixedJoint>
  </gazebo>
  <link name="leg_4/J2_shoulder/INPUT_INTERFACE">
    <visual>
      <origin rpy="0 0 0" xyz="0 0 0"/>
      <geometry>
        <mesh filename="X8.stl" scale="0.001 0.001 0.001"/>
      </geometry>
      <material name="red">
        <color rgba=".82 0.06 0.06 1"/>
      </material>
    </visual>
    <collision>
      <origin rpy="0 0 0" xyz="0 0 0"/>
      <geometry>
        <mesh filename="X8.stl" scale="0.001 0.001 0.001"/>
      </geometry>
    </collision>
    <inertial>
      <origin rpy="0 0 0" xyz="-0.0145 -0.0031 0.0242"/>
      <mass value="0.5"/>
      <inertia ixx="0.000246" ixy="0.0000444" ixz="0.0000266" iyy="0.000380" iyz="0.00000422" izz="0.000463"/>
    </inertial>
  </link>
  <gazebo reference="leg_4/J2_shoulder/INPUT_INTERFACE">
    <material>Gazebo/Red</material>
  </gazebo>
  <joint name="leg_4/J2_shoulder/X8_16" type="revolute">
    <parent link="leg_4/J2_shoulder/INPUT_INTERFACE"/>
    <child link="leg_4/shoulder_elbow/INPUT_INTERFACE"/>
    <origin rpy="0 0 0" xyz="0 0 0.045"/>
    <axis xyz="0 0 1"/>
    <limit effort="38" lower="-0.7853981633974483" upper="0.7853981633974483" velocity="15"/>
    <dynamics damping="0.5" friction="0.5"/>
  </joint>
  <link name="leg_4/shoulder_elbow/INPUT_INTERFACE">
    <!--visual>
        <origin xyz="0 0 0" rpy="0 0 0" />
        <geometry>
          <mesh filename="package://hebi_description/meshes/A-2038-02.stl"/>
        </geometry>
        <xacro:black_material/>
      </visual-->
    <visual>
      <origin rpy="0 1.57075 0" xyz="0.1375 0 0.02"/>
      <geometry>
        <cylinder length="0.24960000000000002" radius=".016"/>
      </geometry>
      <material name="silver">
        <color rgba="0.6 0.6 0.6 1"/>
      </material>
    </visual>
    <!--visual>
        <origin xyz="${extension} ${sin(-twist) * edge_to_center} ${edge_to_center * (1 + cos(-twist))}" rpy="${-twist} 0 0"/>
        <geometry>
          <mesh filename="package://hebi_description/meshes/A-2039-02.stl"/>
        </geometry>
        <xacro:black_material/>
      </visual-->
    <!--collision>
        <origin xyz="0 0 0" rpy="0 0 0" />
        <geometry>
          <mesh filename="package://hebi_description/meshes/A-2038-02.stl"/>
        </geometry>
      </collision-->
    <collision>
      <origin rpy="0 1.57075 0" xyz="0.1375 0 0.02"/>
      <geometry>
        <cylinder length="0.24960000000000002" radius=".016"/>
      </geometry>
    </collision>
    <!--collision>
        <origin xyz="${extension} ${sin(-twist) * edge_to_center} ${edge_to_center * (1 + cos(-twist))}" rpy="${-twist} 0 0"/>
        <geometry>
          <mesh filename="package://hebi_description/meshes/A-2039-02.stl"/>
        </geometry>
      </collision-->
    <!-- Approximate inertia as thin rod about x axis -->
    <inertial>
      <origin rpy="0 0 0" xyz="0.1375 0 0.02"/>
      <mass value="0.382"/>
      <inertia ixx="0.0" ixy="0.0" ixz="0.0" iyy="0.002407395833333334" iyz="0.0" izz="0.002407395833333334"/>
    </inertial>
  </link>
  <gazebo reference="leg_4/shoulder_elbow/INPUT_INTERFACE">
    <material>Gazebo/Grey</material>
  </gazebo>
  <joint name="leg_4/shoulder_elbow/OUTPUT_JOINT" type="fixed">
    <parent link="leg_4/shoulder_elbow/INPUT_INTERFACE"/>
    <child link="leg_4/J3_elbow/INPUT_INTERFACE"/>
    <origin rpy="3.141592653589793 0 0" xyz="0.275 -2.4492935982947064e-18 0.0"/>
  </joint>
  <gazebo reference="leg_4/shoulder_elbow/OUTPUT_JOINT">
    <disableFixedJointLumping>true</disableFixedJointLumping>
    <preserveFixedJoint>true</preserveFixedJoint>
  </gazebo>
  <link name="leg_4/J3_elbow/INPUT_INTERFACE">
    <visual>
      <origin rpy="0 0 0" xyz="0 0 0"/>
      <geometry>
        <mesh filename="X5.stl" scale="0.001 0.001 0.001"/>
      </geometry>
      <material name="red">
        <color rgba=".82 0.06 0.06 1"/>
      </material>
    </visual>
    <collision>
      <origin rpy="0 0 0" xyz="0 0 0"/>
      <geometry>
        <mesh filename="X5.stl" scale="0.001 0.001 0.001"/>
      </geometry>
    </collision>
    <inertial>
      <origin rpy="0 0 0" xyz="-0.0142 -0.0031 0.0165"/>
      <mass value="0.36"/>
      <inertia ixx="0.00015" ixy="0.0000341" ixz="0.0000118" iyy="0.000255" iyz="0.00000229" izz="0.000350"/>
    </inertial>
  </link>
  <gazebo reference="leg_4/J3_elbow/INPUT_INTERFACE">
    <material>Gazebo/Red</material>
  </gazebo>
  <joint name="leg_4/J3_elbow/X5_9" type="revolute">
    <parent link="leg_4/J3_elbow/INPUT_INTERFACE"/>
    <child link="leg_4/elbow_end/INPUT_INTERFACE"/>
    <origin rpy="0 0 0" xyz="0 0 0.031"/>
    <axis xyz="0 0 1"/>
    <limit effort="13.0" lower="0.785" upper="2.356" velocity="14"/>
    <dynamics damping="0.1" friction="0.1"/>
  </joint>
  <link name="leg_4/elbow_end/INPUT_INTERFACE">
    <!--visual>
        <origin xyz="0 0 0" rpy="0 0 0" />
        <geometry>
          <mesh filename="package://hebi_description/meshes/A-2038-02.stl"/>
        </geometry>
        <xacro:black_material/>
      </visual-->
    <visual>
      <origin rpy="0 1.57075 0" xyz="0.1375 0 0.02"/>
      <geometry>
        <cylinder length="0.24960000000000002" radius=".016"/>
      </geometry>
      <material name="silver">
        <color rgba="0.6 0.6 0.6 1"/>
      </material>
    </visual>
    <!--visual>
        <origin xyz="${extension} ${sin(-twist) * edge_to_center} ${edge_to_center * (1 + cos(-twist))}" rpy="${-twist} 0 0"/>
        <geometry>
          <mesh filename="package://hebi_description/meshes/A-2039-02.stl"/>
        </geometry>
        <xacro:black_material/>
      </visual-->
    <!--collision>
        <origin xyz="0 0 0" rpy="0 0 0" />
        <geometry>
          <mesh filename="package://hebi_description/meshes/A-2038-02.stl"/>
        </geometry>
      </collision-->
    <collision>
      <origin rpy="0 1.57075 0" xyz="0.1375 0 0.02"/>
      <geometry>
        <cylinder length="0.24960000000000002" radius=".016"/>
      </geometry>
    </collision>
    <!--collision>
        <origin xyz="${extension} ${sin(-twist) * edge_to_center} ${edge_to_center * (1 + cos(-twist))}" rpy="${-twist} 0 0"/>
        <geometry>
          <mesh filename="package://hebi_description/meshes/A-2039-02.stl"/>
        </geometry>
      </collision-->
    <!-- Approximate inertia as thin rod about x axis -->
    <inertial>
      <origin rpy="0 0 0" xyz="0.1375 0 0.02"/>
      <mass value="0.382"/>
      <inertia ixx="0.0" ixy="0.0" ixz="0.0" iyy="0.002407395833333334" iyz="0.0" izz="0.002407395833333334"/>
    </inertial>
  </link>
  <gazebo reference="leg_4/elbow_end/INPUT_INTERFACE">
    <material>Gazebo/Grey</material>
  </gazebo>
  <joint name="leg_4/elbow_end/OUTPUT_JOINT" type="fixed">
    <parent link="leg_4/elbow_end/INPUT_INTERFACE"/>
    <child link="leg_4/foot/INPUT_INTERFACE"/>
    <origin rpy="0 0 0" xyz="0.275 -0.0 0.04"/>
  </joint>
  <gazebo reference="leg_4/elbow_end/OUTPUT_JOINT">
    <disableFixedJointLumping>true</disableFixedJointLumping>
    <preserveFixedJoint>true</preserveFixedJoint>
  </gazebo>
  <link name="leg_4/foot/INPUT_INTERFACE">
    <inertial>
      <origin rpy="0 0 0" xyz="0 0 -.02"/>
      <mass value="0.01"/>
      <inertia ixx="0.0001" ixy="0" ixz="0" iyy="0.0001" iyz="0" izz="0.0001"/>
    </inertial>
    <visual>
      <geometry>
        <sphere radius="0.025"/>
      </geometry>
      <origin rpy="0 0 0" xyz="0 0 -.02"/>
      <material name="black">
        <color rgba="0.1 0.1 0.1 1"/>
      </material>
    </visual>
    <collision>
      <geometry>
        <sphere radius="0.025"/>
      </geometry>
      <origin rpy="0 0 0" xyz="0 0 -.02"/>
    </collision>
  </link>
  <!-- 
  <xacro:null_end_effector name="leg_${num}/J3_elbow"/>

-->
  <!-- use rubber bit for foot end link; necessary to provide output for HEBI components to attach to. -->
  <!-- No limb at port 5-->
  <!-- connect leg to chassis -->
  <joint name="base_leg_6" type="fixed">
    <parent link="chassis"/>
    <child link="leg_6/J1_base/INPUT_INTERFACE"/>
    <origin rpy="0 0 4.1887902047863905" xyz="0.1524 -0.0880 0.0095"/>
  </joint>
  <link name="leg_6/J1_base/INPUT_INTERFACE">
    <visual>
      <origin rpy="0 0 0" xyz="0 0 0"/>
      <geometry>
        <mesh filename="X8.stl" scale="0.001 0.001 0.001"/>
      </geometry>
      <material name="red">
        <color rgba=".82 0.06 0.06 1"/>
      </material>
    </visual>
    <collision>
      <origin rpy="0 0 0" xyz="0 0 0"/>
      <geometry>
        <mesh filename="X8.stl" scale="0.001 0.001 0.001"/>
      </geometry>
    </collision>
    <inertial>
      <origin rpy="0 0 0" xyz="-0.0145 -0.0031 0.0242"/>
      <mass value="0.48"/>
      <inertia ixx="0.000246" ixy="0.0000444" ixz="0.0000266" iyy="0.000380" iyz="0.00000422" izz="0.000463"/>
    </inertial>
  </link>
  <gazebo reference="leg_6/J1_base/INPUT_INTERFACE">
    <material>Gazebo/Red</material>
  </gazebo>
  <joint name="leg_6/J1_base/X8_9" type="revolute">
    <parent link="leg_6/J1_base/INPUT_INTERFACE"/>
    <child link="leg_6/shoulder_bracket/INPUT_INTERFACE"/>
    <origin rpy="0 0 0" xyz="0 0 0.045"/>
    <axis xyz="0 0 1"/>
    <limit effort="20" lower="0.5235987755982988" upper="2.6179938779914944" velocity="30"/>
    <dynamics damping="0.5" friction="0.5"/>
  </joint>
  <link name="leg_6/shoulder_bracket/INPUT_INTERFACE">
    <!-- REMOVED VISUAL AND COLLISION FOR SPEED
      <visual>
        <xacro:if value="${bracket_type.endswith('RightOutside')}">
          <origin xyz="0 0 0.005" rpy="${pi/2} 0 ${pi/2}"/>
        </xacro:if>
        <xacro:if value="${bracket_type.endswith('RightInside')}">
          <origin xyz="0 0 0.005" rpy="${pi/2} 0 ${-pi/2}"/>
        </xacro:if>
        <xacro:if value="${bracket_type.endswith('LeftOutside')}">
          <origin xyz="0 0 0.005" rpy="${pi/2} 0 ${-pi/2}"/>
        </xacro:if>
        <xacro:if value="${bracket_type.endswith('LeftInside')}">
          <origin xyz="0 0 0.005" rpy="${pi/2} 0 ${pi/2}"/>
        </xacro:if>
        <geometry>
          <mesh filename="PM-2149-01.stl" scale="0.001 0.001 0.001"/>
        </geometry>
        <xacro:black_material/>
      </visual>
      <visual>
        <xacro:if value="${bracket_type.endswith('RightOutside')}">
          <origin xyz="0 -.03 .04" rpy="${pi/2} 0 0"/>
        </xacro:if>
        <xacro:if value="${bracket_type.endswith('RightInside')}">
          <origin xyz="0 .03 .04" rpy="${pi/2} 0 0"/>
        </xacro:if>
        <xacro:if value="${bracket_type.endswith('LeftOutside')}">
          <origin xyz="0 -.03 .04" rpy="${pi/2} 0 0"/>
        </xacro:if>
        <xacro:if value="${bracket_type.endswith('LeftInside')}">
          <origin xyz="0 -.03 .04" rpy="${pi/2} 0 ${pi}"/>
        </xacro:if>
        <geometry>
          <xacro:if value="${bracket_type.startswith('X5HeavyRight') or bracket_type.startswith('R5HeavyRight')}">
            <mesh filename="PM-2150-01R.stl" scale="0.001 0.001 0.001"/>
          </xacro:if>
          <xacro:if value="${bracket_type.startswith('X5HeavyLeft') or bracket_type.startswith('R5HeavyLeft')}">
            <mesh filename="PM-2150-01L.stl" scale="0.001 0.001 0.001"/>
          </xacro:if>
        </geometry>
        <xacro:black_material/>
      </visual>

      <collision>
        <xacro:if value="${bracket_type.endswith('RightOutside')}">
          <origin xyz="0 0 0.005" rpy="${pi/2} 0 ${pi/2}"/>
        </xacro:if>
        <xacro:if value="${bracket_type.endswith('RightInside')}">
          <origin xyz="0 0 0.005" rpy="${pi/2} 0 ${-pi/2}"/>
        </xacro:if>
        <xacro:if value="${bracket_type.endswith('LeftOutside')}">
          <origin xyz="0 0 0.005" rpy="${pi/2} 0 ${-pi/2}"/>
        </xacro:if>
        <xacro:if value="${bracket_type.endswith('LeftInside')}">
          <origin xyz="0 0 0.005" rpy="${pi/2} 0 ${pi/2}"/>
        </xacro:if>
        <geometry>
          <mesh filename="PM-2149-01.stl" scale="0.001 0.001 0.001"/>
        </geometry>
      </collision>
      <collision>
        <xacro:if value="${bracket_type.endswith('RightOutside')}">
          <origin xyz="0 -.03 .04" rpy="${pi/2} 0 0"/>
        </xacro:if>
        <xacro:if value="${bracket_type.endswith('RightInside')}">
          <origin xyz="0 .03 .04" rpy="${pi/2} 0 0"/>
        </xacro:if>
        <xacro:if value="${bracket_type.endswith('LeftOutside')}">
          <origin xyz="0 .03 .04" rpy="${pi/2} 0 ${pi}"/>
        </xacro:if>
        <xacro:if value="${bracket_type.endswith('LeftInside')}">
          <origin xyz="0 -.03 .04" rpy="${pi/2} 0 ${pi}"/>
        </xacro:if>
        <geometry>
          <xacro:if value="${bracket_type.startswith('X5HeavyRight') or bracket_type.startswith('R5HeavyRight')}">
            <mesh filename="PM-2150-01R.stl" scale="0.001 0.001 0.001"/>
          </xacro:if>
          <xacro:if value="${bracket_type.startswith('X5HeavyLeft') or bracket_type.startswith('R5HeavyLeft')}">
            <mesh filename="PM-2150-01L.stl" scale="0.001 0.001 0.001"/>
          </xacro:if>
        </geometry>
      </collision>
      -->
    <!-- NOTE: inertia is just modelled as small sphere, and could be improved. -->
    <inertial>
      <origin rpy="0 0 0" xyz="0 0.01125 .0275"/>
      <mass value="0.215"/>
      <inertia ixx="0.00030960000000000004" ixy="0.0" ixz="0.0" iyy="0.00030960000000000004" iyz="0.0" izz="0.00030960000000000004"/>
    </inertial>
  </link>
  <gazebo reference="leg_6/shoulder_bracket/INPUT_INTERFACE">
    <material>Gazebo/Black</material>
  </gazebo>
  <joint name="leg_6/shoulder_bracket/OUTPUT_INTERFACE" type="fixed">
    <parent link="leg_6/shoulder_bracket/INPUT_INTERFACE"/>
    <child link="leg_6/J2_shoulder/INPUT_INTERFACE"/>
    <origin rpy="1.5707963267948966 0 0" xyz="0 .0225 .055"/>
  </joint>
  <gazebo reference="leg_6/shoulder_bracket/OUTPUT_INTERFACE">
    <disableFixedJointLumping>true</disableFixedJointLumping>
    <preserveFixedJoint>true</preserveFixedJoint>
  </gazebo>
  <link name="leg_6/J2_shoulder/INPUT_INTERFACE">
    <visual>
      <origin rpy="0 0 0" xyz="0 0 0"/>
      <geometry>
        <mesh filename="X8.stl" scale="0.001 0.001 0.001"/>
      </geometry>
      <material name="red">
        <color rgba=".82 0.06 0.06 1"/>
      </material>
    </visual>
    <collision>
      <origin rpy="0 0 0" xyz="0 0 0"/>
      <geometry>
        <mesh filename="X8.stl" scale="0.001 0.001 0.001"/>
      </geometry>
    </collision>
    <inertial>
      <origin rpy="0 0 0" xyz="-0.0145 -0.0031 0.0242"/>
      <mass value="0.5"/>
      <inertia ixx="0.000246" ixy="0.0000444" ixz="0.0000266" iyy="0.000380" iyz="0.00000422" izz="0.000463"/>
    </inertial>
  </link>
  <gazebo reference="leg_6/J2_shoulder/INPUT_INTERFACE">
    <material>Gazebo/Red</material>
  </gazebo>
  <joint name="leg_6/J2_shoulder/X8_16" type="revolute">
    <parent link="leg_6/J2_shoulder/INPUT_INTERFACE"/>
    <child link="leg_6/shoulder_elbow/INPUT_INTERFACE"/>
    <origin rpy="0 0 0" xyz="0 0 0.045"/>
    <axis xyz="0 0 1"/>
    <limit effort="38" lower="-0.7853981633974483" upper="0.7853981633974483" velocity="15"/>
    <dynamics damping="0.5" friction="0.5"/>
  </joint>
  <link name="leg_6/shoulder_elbow/INPUT_INTERFACE">
    <!--visual>
        <origin xyz="0 0 0" rpy="0 0 0" />
        <geometry>
          <mesh filename="package://hebi_description/meshes/A-2038-02.stl"/>
        </geometry>
        <xacro:black_material/>
      </visual-->
    <visual>
      <origin rpy="0 1.57075 0" xyz="0.1375 0 0.02"/>
      <geometry>
        <cylinder length="0.24960000000000002" radius=".016"/>
      </geometry>
      <material name="silver">
        <color rgba="0.6 0.6 0.6 1"/>
      </material>
    </visual>
    <!--visual>
        <origin xyz="${extension} ${sin(-twist) * edge_to_center} ${edge_to_center * (1 + cos(-twist))}" rpy="${-twist} 0 0"/>
        <geometry>
          <mesh filename="package://hebi_description/meshes/A-2039-02.stl"/>
        </geometry>
        <xacro:black_material/>
      </visual-->
    <!--collision>
        <origin xyz="0 0 0" rpy="0 0 0" />
        <geometry>
          <mesh filename="package://hebi_description/meshes/A-2038-02.stl"/>
        </geometry>
      </collision-->
    <collision>
      <origin rpy="0 1.57075 0" xyz="0.1375 0 0.02"/>
      <geometry>
        <cylinder length="0.24960000000000002" radius=".016"/>
      </geometry>
    </collision>
    <!--collision>
        <origin xyz="${extension} ${sin(-twist) * edge_to_center} ${edge_to_center * (1 + cos(-twist))}" rpy="${-twist} 0 0"/>
        <geometry>
          <mesh filename="package://hebi_description/meshes/A-2039-02.stl"/>
        </geometry>
      </collision-->
    <!-- Approximate inertia as thin rod about x axis -->
    <inertial>
      <origin rpy="0 0 0" xyz="0.1375 0 0.02"/>
      <mass value="0.382"/>
      <inertia ixx="0.0" ixy="0.0" ixz="0.0" iyy="0.002407395833333334" iyz="0.0" izz="0.002407395833333334"/>
    </inertial>
  </link>
  <gazebo reference="leg_6/shoulder_elbow/INPUT_INTERFACE">
    <material>Gazebo/Grey</material>
  </gazebo>
  <joint name="leg_6/shoulder_elbow/OUTPUT_JOINT" type="fixed">
    <parent link="leg_6/shoulder_elbow/INPUT_INTERFACE"/>
    <child link="leg_6/J3_elbow/INPUT_INTERFACE"/>
    <origin rpy="3.141592653589793 0 0" xyz="0.275 -2.4492935982947064e-18 0.0"/>
  </joint>
  <gazebo reference="leg_6/shoulder_elbow/OUTPUT_JOINT">
    <disableFixedJointLumping>true</disableFixedJointLumping>
    <preserveFixedJoint>true</preserveFixedJoint>
  </gazebo>
  <link name="leg_6/J3_elbow/INPUT_INTERFACE">
    <visual>
      <origin rpy="0 0 0" xyz="0 0 0"/>
      <geometry>
        <mesh filename="X5.stl" scale="0.001 0.001 0.001"/>
      </geometry>
      <material name="red">
        <color rgba=".82 0.06 0.06 1"/>
      </material>
    </visual>
    <collision>
      <origin rpy="0 0 0" xyz="0 0 0"/>
      <geometry>
        <mesh filename="X5.stl" scale="0.001 0.001 0.001"/>
      </geometry>
    </collision>
    <inertial>
      <origin rpy="0 0 0" xyz="-0.0142 -0.0031 0.0165"/>
      <mass value="0.36"/>
      <inertia ixx="0.00015" ixy="0.0000341" ixz="0.0000118" iyy="0.000255" iyz="0.00000229" izz="0.000350"/>
    </inertial>
  </link>
  <gazebo reference="leg_6/J3_elbow/INPUT_INTERFACE">
    <material>Gazebo/Red</material>
  </gazebo>
  <joint name="leg_6/J3_elbow/X5_9" type="revolute">
    <parent link="leg_6/J3_elbow/INPUT_INTERFACE"/>
    <child link="leg_6/elbow_end/INPUT_INTERFACE"/>
    <origin rpy="0 0 0" xyz="0 0 0.031"/>
    <axis xyz="0 0 1"/>
    <limit effort="13.0" lower="0.785" upper="2.356" velocity="14"/>
    <dynamics damping="0.1" friction="0.1"/>
  </joint>
  <link name="leg_6/elbow_end/INPUT_INTERFACE">
    <!--visual>
        <origin xyz="0 0 0" rpy="0 0 0" />
        <geometry>
          <mesh filename="package://hebi_description/meshes/A-2038-02.stl"/>
        </geometry>
        <xacro:black_material/>
      </visual-->
    <visual>
      <origin rpy="0 1.57075 0" xyz="0.1375 0 0.02"/>
      <geometry>
        <cylinder length="0.24960000000000002" radius=".016"/>
      </geometry>
      <material name="silver">
        <color rgba="0.6 0.6 0.6 1"/>
      </material>
    </visual>
    <!--visual>
        <origin xyz="${extension} ${sin(-twist) * edge_to_center} ${edge_to_center * (1 + cos(-twist))}" rpy="${-twist} 0 0"/>
        <geometry>
          <mesh filename="package://hebi_description/meshes/A-2039-02.stl"/>
        </geometry>
        <xacro:black_material/>
      </visual-->
    <!--collision>
        <origin xyz="0 0 0" rpy="0 0 0" />
        <geometry>
          <mesh filename="package://hebi_description/meshes/A-2038-02.stl"/>
        </geometry>
      </collision-->
    <collision>
      <origin rpy="0 1.57075 0" xyz="0.1375 0 0.02"/>
      <geometry>
        <cylinder length="0.24960000000000002" radius=".016"/>
      </geometry>
    </collision>
    <!--collision>
        <origin xyz="${extension} ${sin(-twist) * edge_to_center} ${edge_to_center * (1 + cos(-twist))}" rpy="${-twist} 0 0"/>
        <geometry>
          <mesh filename="package://hebi_description/meshes/A-2039-02.stl"/>
        </geometry>
      </collision-->
    <!-- Approximate inertia as thin rod about x axis -->
    <inertial>
      <origin rpy="0 0 0" xyz="0.1375 0 0.02"/>
      <mass value="0.382"/>
      <inertia ixx="0.0" ixy="0.0" ixz="0.0" iyy="0.002407395833333334" iyz="0.0" izz="0.002407395833333334"/>
    </inertial>
  </link>
  <gazebo reference="leg_6/elbow_end/INPUT_INTERFACE">
    <material>Gazebo/Grey</material>
  </gazebo>
  <joint name="leg_6/elbow_end/OUTPUT_JOINT" type="fixed">
    <parent link="leg_6/elbow_end/INPUT_INTERFACE"/>
    <child link="leg_6/foot/INPUT_INTERFACE"/>
    <origin rpy="0 0 0" xyz="0.275 -0.0 0.04"/>
  </joint>
  <gazebo reference="leg_6/elbow_end/OUTPUT_JOINT">
    <disableFixedJointLumping>true</disableFixedJointLumping>
    <preserveFixedJoint>true</preserveFixedJoint>
  </gazebo>
  <link name="leg_6/foot/INPUT_INTERFACE">
    <inertial>
      <origin rpy="0 0 0" xyz="0 0 -.02"/>
      <mass value="0.01"/>
      <inertia ixx="0.0001" ixy="0" ixz="0" iyy="0.0001" iyz="0" izz="0.0001"/>
    </inertial>
    <visual>
      <geometry>
        <sphere radius="0.025"/>
      </geometry>
      <origin rpy="0 0 0" xyz="0 0 -.02"/>
      <material name="black">
        <color rgba="0.1 0.1 0.1 1"/>
      </material>
    </visual>
    <collision>
      <geometry>
        <sphere radius="0.025"/>
      </geometry>
      <origin rpy="0 0 0" xyz="0 0 -.02"/>
    </collision>
  </link>
  <!-- 
  <xacro:null_end_effector name="leg_${num}/J3_elbow"/>

-->
  <!-- use rubber bit for foot end link; necessary to provide output for HEBI components to attach to. -->
</robot>

